Workbook
Name Jogo1: #REF!
Name Jogo1Time1: #REF!
Name Jogo1Time2: #REF!
Name Jogo2: #REF!
Name Jogo2Time1: #REF!
Name Jogo2Time2: #REF!
Name Jogo3: #REF!
Name Jogo3Time1: #REF!
Name Jogo3Time2: #REF!
Name Jogo4: #REF!
Name Jogo4Time1: #REF!
Name jogo4Time2: #REF!
Name Jogo5: #REF!
Name Jogo5Time1: #REF!
Name Jogo5Time2: #REF!
Name Jogo6: #REF!
Name Jogo6Time1: #REF!
Name Jogo6Time2: #REF!
Name Jogo7: #REF!
Name Jogo7Time1: #REF!
Name Jogo7Time2: #REF!
Name Jogo8: #REF!
Name Jogo8Time1: #REF!
Name Jogo8Time2: #REF!

Sheet Aux
A1: Email:
A2: lppelada@gmail.com
A3: lpp@1995

Sheet Resumo
B2: A | C2: Assiduidade
B3: G | C3: Gols
B4: P | C4: Pontos | F4: TOTAL | H4: Janeiro | L4: Fevereiro | P4: Março | U4: Abril | Y4: Maio | AC4: Junho | AH4: Julho | AL4: Agosto | AQ4: Setembro | AU4: Outubro | AY4: Novembro | BD4: Dezembro
H5: w1 | I5: w2 | J5: w3 | K5: w4 | L5: w5 | M5: w6 | N5: w7 | O5: w8 | P5: w9 | Q5: w10 | R5: w11 | S5: w12 | T5: w13 | U5: w14 | V5: w15 | W5: w16 | X5: w17 | Y5: w18 | Z5: w19 | AA5: w20 | AB5: w21 | AC5: w22 | AD5: w23 | AE5: w24 | AF5: w25 | AG5: w26 | AH5: w27 | AI5: w28 | AJ5: w29 | AK5: w30 | AL5: w31 | AM5: w32 | AN5: w33 | AO5: w34 | AP5: w35 | AQ5: w36 | AR5: w37 | AS5: w38 | AT5: w39 | AU5: w40 | AV5: w41 | AW5: w42 | AX5: w43 | AY5: w44 | AZ5: w45 | BA5: w46 | BB5: w47 | BC5: w48 | BD5: w49 | BE5: w50 | BF5: w51 | BG5: w52
B6: # | C6: Nome | E6: # | H6: 45662 | I6: =H6+7 -> 45669 | J6: =I6+7 -> 45676 | K6: =J6+7 -> 45683 | L6: =K6+7 -> 45690 | M6: =L6+7 -> 45697 | N6: =M6+7 -> 45704 | O6: =N6+7 -> 45711 | P6: =O6+7 -> 45718 | ... BG6: =BF6+7 -> 46019
B7: G | C7: Fabio | D7: =IF(C7="","",C7) -> Fabio | E7: =IF(B7="","",B7) -> G | F7: A | G7: =SUM(H7:BG7) -> 25 | H7: =IFERROR(IF(VLOOKUP($C7,INDIRECT(H$5&"!$V$3:$AG$100"),2,0)>0,1,0),"") | I7: =IFERROR(IF(VLOOKUP($C7,INDIRECT(I$5&"!$V$3:$AG$100"),2,0)>0,1,0),"") -> 1 | J7: =IFERROR(IF(VLOOKUP($C7,INDIRECT(J$5&"!$V$3:$AG$100"),2,0)>0,1,0),"") -> 1 | K7: =IFERROR(IF(VLOOKUP($C7,INDIRECT(K$5&"!$V$3:$AG$100"),2,0)>0,1,0),"") -> 1 | L7: =IFERROR(IF(VLOOKUP($C7,INDIRECT(L$5&"!$V$3:$AG$100"),2,0)>0,1,0),"") | M7: =IFERROR(IF(VLOOKUP($C7,INDIRECT(M$5&"!$V$3:$AG$100"),2,0)>0,1,0),"") | N7: =IFERROR(IF(VLOOKUP($C7,INDIRECT(N$5&"!$V$3:$AG$100"),2,0)>0,1,0),"") -> 1 | O7: =IFERROR(IF(VLOOKUP($C7,INDIRECT(O$5&"!$V$3:$AG$100"),2,0)>0,1,0),"") | ... BG7: =IFERROR(IF(VLOOKUP($C7,INDIRECT(BG$5&"!$V$3:$AG$100"),2,0)>0,1,0),"")
D8: =IF(C8="","",C8) | E8: =IF(B8="","",B8) | F8: G | G8: =SUM(H8:BG8) -> 0 | H8: =IFERROR(IF(VLOOKUP($C7,INDIRECT(H$5&"!$V$3:$AG$100"),12,0)>0,VLOOKUP($C7,INDIRECT(H$5&"!$V$3:$AG$100"),12,0),0),"") | I8: =IFERROR(IF(VLOOKUP($C7,INDIRECT(I$5&"!$V$3:$AG$100"),12,0)>0,VLOOKUP($C7,INDIRECT(I$5&"!$V$3:$AG$100"),12,0),0),"") -> 0 | J8: =IFERROR(IF(VLOOKUP($C7,INDIRECT(J$5&"!$V$3:$AG$100"),12,0)>0,VLOOKUP($C7,INDIRECT(J$5&"!$V$3:$AG$100"),12,0),0),"") -> 0 | K8: =IFERROR(IF(VLOOKUP($C7,INDIRECT(K$5&"!$V$3:$AG$100"),12,0)>0,VLOOKUP($C7,INDIRECT(K$5&"!$V$3:$AG$100"),12,0),0),"") -> 0 | L8: =IFERROR(IF(VLOOKUP($C7,INDIRECT(L$5&"!$V$3:$AG$100"),12,0)>0,VLOOKUP($C7,INDIRECT(L$5&"!$V$3:$AG$100"),12,0),0),"") | M8: =IFERROR(IF(VLOOKUP($C7,INDIRECT(M$5&"!$V$3:$AG$100"),12,0)>0,VLOOKUP($C7,INDIRECT(M$5&"!$V$3:$AG$100"),12,0),0),"") | N8: =IFERROR(IF(VLOOKUP($C7,INDIRECT(N$5&"!$V$3:$AG$100"),12,0)>0,VLOOKUP($C7,INDIRECT(N$5&"!$V$3:$AG$100"),12,0),0),"") -> 0 | O8: =IFERROR(IF(VLOOKUP($C7,INDIRECT(O$5&"!$V$3:$AG$100"),12,0)>0,VLOOKUP($C7,INDIRECT(O$5&"!$V$3:$AG$100"),12,0),0),"") | ... BG8: =IFERROR(IF(VLOOKUP($C7,INDIRECT(BG$5&"!$V$3:$AG$100"),12,0)>0,VLOOKUP($C7,INDIRECT(BG$5&"!$V$3:$AG$100"),12,0),0),"")
D9: =IF(C9="","",C9) | E9: =IF(B9="","",B9) | F9: P | G9: =SUM(H9:BG9) -> 233 | H9: =IFERROR(IF(VLOOKUP($C7,INDIRECT(H$5&"!$V$3:$AG$100"),11,0)>0,VLOOKUP($C7,INDIRECT(H$5&"!$V$3:$AG$100"),11,0),0),"") | I9: =IFERROR(IF(VLOOKUP($C7,INDIRECT(I$5&"!$V$3:$AG$100"),11,0)>0,VLOOKUP($C7,INDIRECT(I$5&"!$V$3:$AG$100"),11,0),0),"") -> 7 | J9: =IFERROR(IF(VLOOKUP($C7,INDIRECT(J$5&"!$V$3:$AG$100"),11,0)>0,VLOOKUP($C7,INDIRECT(J$5&"!$V$3:$AG$100"),11,0),0),"") -> 14 | K9: =IFERROR(IF(VLOOKUP($C7,INDIRECT(K$5&"!$V$3:$AG$100"),11,0)>0,VLOOKUP($C7,INDIRECT(K$5&"!$V$3:$AG$100"),11,0),0),"") -> 10 | L9: =IFERROR(IF(VLOOKUP($C7,INDIRECT(L$5&"!$V$3:$AG$100"),11,0)>0,VLOOKUP($C7,INDIRECT(L$5&"!$V$3:$AG$100"),11,0),0),"") | M9: =IFERROR(IF(VLOOKUP($C7,INDIRECT(M$5&"!$V$3:$AG$100"),11,0)>0,VLOOKUP($C7,INDIRECT(M$5&"!$V$3:$AG$100"),11,0),0),"") | N9: =IFERROR(IF(VLOOKUP($C7,INDIRECT(N$5&"!$V$3:$AG$100"),11,0)>0,VLOOKUP($C7,INDIRECT(N$5&"!$V$3:$AG$100"),11,0),0),"") -> 19 | O9: =IFERROR(IF(VLOOKUP($C7,INDIRECT(O$5&"!$V$3:$AG$100"),11,0)>0,VLOOKUP($C7,INDIRECT(O$5&"!$V$3:$AG$100"),11,0),0),"") | ... BG9: =IFERROR(IF(VLOOKUP($C7,INDIRECT(BG$5&"!$V$3:$AG$100"),11,0)>0,VLOOKUP($C7,INDIRECT(BG$5&"!$V$3:$AG$100"),11,0),0),"")
B10: G | C10: Ralph | D10: =IF(C10="","",C10) -> Ralph | E10: =IF(B10="","",B10) -> G | F10: A | G10: =SUM(H10:BG10) -> 27 | H10: =IFERROR(IF(VLOOKUP($C10,INDIRECT(H$5&"!$V$3:$AG$100"),2,0)>0,1,0),"") | I10: =IFERROR(IF(VLOOKUP($C10,INDIRECT(I$5&"!$V$3:$AG$100"),2,0)>0,1,0),"") -> 1 | J10: =IFERROR(IF(VLOOKUP($C10,INDIRECT(J$5&"!$V$3:$AG$100"),2,0)>0,1,0),"") -> 1 | K10: =IFERROR(IF(VLOOKUP($C10,INDIRECT(K$5&"!$V$3:$AG$100"),2,0)>0,1,0),"") | L10: =IFERROR(IF(VLOOKUP($C10,INDIRECT(L$5&"!$V$3:$AG$100"),2,0)>0,1,0),"") | M10: =IFERROR(IF(VLOOKUP($C10,INDIRECT(M$5&"!$V$3:$AG$100"),2,0)>0,1,0),"") | N10: =IFERROR(IF(VLOOKUP($C10,INDIRECT(N$5&"!$V$3:$AG$100"),2,0)>0,1,0),"") | O10: =IFERROR(IF(VLOOKUP($C10,INDIRECT(O$5&"!$V$3:$AG$100"),2,0)>0,1,0),"") -> 1 | ... BG10: =IFERROR(IF(VLOOKUP($C10,INDIRECT(BG$5&"!$V$3:$AG$100"),2,0)>0,1,0),"")
D11: =IF(C11="","",C11) | E11: =IF(B11="","",B11) | F11: G | G11: =SUM(H11:BG11) -> 0 | H11: =IFERROR(IF(VLOOKUP($C10,INDIRECT(H$5&"!$V$3:$AG$100"),12,0)>0,VLOOKUP($C10,INDIRECT(H$5&"!$V$3:$AG$100"),12,0),0),"") | I11: =IFERROR(IF(VLOOKUP($C10,INDIRECT(I$5&"!$V$3:$AG$100"),12,0)>0,VLOOKUP($C10,INDIRECT(I$5&"!$V$3:$AG$100"),12,0),0),"") -> 0 | J11: =IFERROR(IF(VLOOKUP($C10,INDIRECT(J$5&"!$V$3:$AG$100"),12,0)>0,VLOOKUP($C10,INDIRECT(J$5&"!$V$3:$AG$100"),12,0),0),"") -> 0 | K11: =IFERROR(IF(VLOOKUP($C10,INDIRECT(K$5&"!$V$3:$AG$100"),12,0)>0,VLOOKUP($C10,INDIRECT(K$5&"!$V$3:$AG$100"),12,0),0),"") | L11: =IFERROR(IF(VLOOKUP($C10,INDIRECT(L$5&"!$V$3:$AG$100"),12,0)>0,VLOOKUP($C10,INDIRECT(L$5&"!$V$3:$AG$100"),12,0),0),"") | M11: =IFERROR(IF(VLOOKUP($C10,INDIRECT(M$5&"!$V$3:$AG$100"),12,0)>0,VLOOKUP($C10,INDIRECT(M$5&"!$V$3:$AG$100"),12,0),0),"") | N11: =IFERROR(IF(VLOOKUP($C10,INDIRECT(N$5&"!$V$3:$AG$100"),12,0)>0,VLOOKUP($C10,INDIRECT(N$5&"!$V$3:$AG$100"),12,0),0),"") | O11: =IFERROR(IF(VLOOKUP($C10,INDIRECT(O$5&"!$V$3:$AG$100"),12,0)>0,VLOOKUP($C10,INDIRECT(O$5&"!$V$3:$AG$100"),12,0),0),"") -> 0 | ... BG11: =IFERROR(IF(VLOOKUP($C10,INDIRECT(BG$5&"!$V$3:$AG$100"),12,0)>0,VLOOKUP($C10,INDIRECT(BG$5&"!$V$3:$AG$100"),12,0),0),"")
D12: =IF(C12="","",C12) | E12: =IF(B12="","",B12) | F12: P | G12: =SUM(H12:BG12) -> 262 | H12: =IFERROR(IF(VLOOKUP($C10,INDIRECT(H$5&"!$V$3:$AG$100"),11,0)>0,VLOOKUP($C10,INDIRECT(H$5&"!$V$3:$AG$100"),11,0),0),"") | I12: =IFERROR(IF(VLOOKUP($C10,INDIRECT(I$5&"!$V$3:$AG$100"),11,0)>0,VLOOKUP($C10,INDIRECT(I$5&"!$V$3:$AG$100"),11,0),0),"") -> 14 | J12: =IFERROR(IF(VLOOKUP($C10,INDIRECT(J$5&"!$V$3:$AG$100"),11,0)>0,VLOOKUP($C10,INDIRECT(J$5&"!$V$3:$AG$100"),11,0),0),"") -> 7 | K12: =IFERROR(IF(VLOOKUP($C10,INDIRECT(K$5&"!$V$3:$AG$100"),11,0)>0,VLOOKUP($C10,INDIRECT(K$5&"!$V$3:$AG$100"),11,0),0),"") | L12: =IFERROR(IF(VLOOKUP($C10,INDIRECT(L$5&"!$V$3:$AG$100"),11,0)>0,VLOOKUP($C10,INDIRECT(L$5&"!$V$3:$AG$100"),11,0),0),"") | M12: =IFERROR(IF(VLOOKUP($C10,INDIRECT(M$5&"!$V$3:$AG$100"),11,0)>0,VLOOKUP($C10,INDIRECT(M$5&"!$V$3:$AG$100"),11,0),0),"") | N12: =IFERROR(IF(VLOOKUP($C10,INDIRECT(N$5&"!$V$3:$AG$100"),11,0)>0,VLOOKUP($C10,INDIRECT(N$5&"!$V$3:$AG$100"),11,0),0),"") | O12: =IFERROR(IF(VLOOKUP($C10,INDIRECT(O$5&"!$V$3:$AG$100"),11,0)>0,VLOOKUP($C10,INDIRECT(O$5&"!$V$3:$AG$100"),11,0),0),"") -> 6 | ... BG12: =IFERROR(IF(VLOOKUP($C10,INDIRECT(BG$5&"!$V$3:$AG$100"),11,0)>0,VLOOKUP($C10,INDIRECT(BG$5&"!$V$3:$AG$100"),11,0),0),"")
B13: G | D13: =IF(C13="","",C13) | E13: =IF(B13="","",B13) -> G | F13: A | G13: =SUM(H13:BG13) -> 0 | H13: =IFERROR(IF(VLOOKUP($C13,INDIRECT(H$5&"!$V$3:$AG$100"),2,0)>0,1,0),"") | I13: =IFERROR(IF(VLOOKUP($C13,INDIRECT(I$5&"!$V$3:$AG$100"),2,0)>0,1,0),"") | J13: =IFERROR(IF(VLOOKUP($C13,INDIRECT(J$5&"!$V$3:$AG$100"),2,0)>0,1,0),"") | K13: =IFERROR(IF(VLOOKUP($C13,INDIRECT(K$5&"!$V$3:$AG$100"),2,0)>0,1,0),"") | L13: =IFERROR(IF(VLOOKUP($C13,INDIRECT(L$5&"!$V$3:$AG$100"),2,0)>0,1,0),"") | M13: =IFERROR(IF(VLOOKUP($C13,INDIRECT(M$5&"!$V$3:$AG$100"),2,0)>0,1,0),"") | N13: =IFERROR(IF(VLOOKUP($C13,INDIRECT(N$5&"!$V$3:$AG$100"),2,0)>0,1,0),"") | O13: =IFERROR(IF(VLOOKUP($C13,INDIRECT(O$5&"!$V$3:$AG$100"),2,0)>0,1,0),"") | ... BG13: =IFERROR(IF(VLOOKUP($C13,INDIRECT(BG$5&"!$V$3:$AG$100"),2,0)>0,1,0),"")
D14: =IF(C14="","",C14) | E14: =IF(B14="","",B14) | F14: G | G14: =SUM(H14:BG14) -> 0 | H14: =IFERROR(IF(VLOOKUP($C13,INDIRECT(H$5&"!$V$3:$AG$100"),12,0)>0,VLOOKUP($C13,INDIRECT(H$5&"!$V$3:$AG$100"),12,0),0),"") | I14: =IFERROR(IF(VLOOKUP($C13,INDIRECT(I$5&"!$V$3:$AG$100"),12,0)>0,VLOOKUP($C13,INDIRECT(I$5&"!$V$3:$AG$100"),12,0),0),"") | J14: =IFERROR(IF(VLOOKUP($C13,INDIRECT(J$5&"!$V$3:$AG$100"),12,0)>0,VLOOKUP($C13,INDIRECT(J$5&"!$V$3:$AG$100"),12,0),0),"") | K14: =IFERROR(IF(VLOOKUP($C13,INDIRECT(K$5&"!$V$3:$AG$100"),12,0)>0,VLOOKUP($C13,INDIRECT(K$5&"!$V$3:$AG$100"),12,0),0),"") | L14: =IFERROR(IF(VLOOKUP($C13,INDIRECT(L$5&"!$V$3:$AG$100"),12,0)>0,VLOOKUP($C13,INDIRECT(L$5&"!$V$3:$AG$100"),12,0),0),"") | M14: =IFERROR(IF(VLOOKUP($C13,INDIRECT(M$5&"!$V$3:$AG$100"),12,0)>0,VLOOKUP($C13,INDIRECT(M$5&"!$V$3:$AG$100"),12,0),0),"") | N14: =IFERROR(IF(VLOOKUP($C13,INDIRECT(N$5&"!$V$3:$AG$100"),12,0)>0,VLOOKUP($C13,INDIRECT(N$5&"!$V$3:$AG$100"),12,0),0),"") | O14: =IFERROR(IF(VLOOKUP($C13,INDIRECT(O$5&"!$V$3:$AG$100"),12,0)>0,VLOOKUP($C13,INDIRECT(O$5&"!$V$3:$AG$100"),12,0),0),"") | ... BG14: =IFERROR(IF(VLOOKUP($C13,INDIRECT(BG$5&"!$V$3:$AG$100"),12,0)>0,VLOOKUP($C13,INDIRECT(BG$5&"!$V$3:$AG$100"),12,0),0),"")
D15: =IF(C15="","",C15) | E15: =IF(B15="","",B15) | F15: P | G15: =SUM(H15:BG15) -> 0 | H15: =IFERROR(IF(VLOOKUP($C13,INDIRECT(H$5&"!$V$3:$AG$100"),11,0)>0,VLOOKUP($C13,INDIRECT(H$5&"!$V$3:$AG$100"),11,0),0),"") | I15: =IFERROR(IF(VLOOKUP($C13,INDIRECT(I$5&"!$V$3:$AG$100"),11,0)>0,VLOOKUP($C13,INDIRECT(I$5&"!$V$3:$AG$100"),11,0),0),"") | J15: =IFERROR(IF(VLOOKUP($C13,INDIRECT(J$5&"!$V$3:$AG$100"),11,0)>0,VLOOKUP($C13,INDIRECT(J$5&"!$V$3:$AG$100"),11,0),0),"") | K15: =IFERROR(IF(VLOOKUP($C13,INDIRECT(K$5&"!$V$3:$AG$100"),11,0)>0,VLOOKUP($C13,INDIRECT(K$5&"!$V$3:$AG$100"),11,0),0),"") | L15: =IFERROR(IF(VLOOKUP($C13,INDIRECT(L$5&"!$V$3:$AG$100"),11,0)>0,VLOOKUP($C13,INDIRECT(L$5&"!$V$3:$AG$100"),11,0),0),"") | M15: =IFERROR(IF(VLOOKUP($C13,INDIRECT(M$5&"!$V$3:$AG$100"),11,0)>0,VLOOKUP($C13,INDIRECT(M$5&"!$V$3:$AG$100"),11,0),0),"") | N15: =IFERROR(IF(VLOOKUP($C13,INDIRECT(N$5&"!$V$3:$AG$100"),11,0)>0,VLOOKUP($C13,INDIRECT(N$5&"!$V$3:$AG$100"),11,0),0),"") | O15: =IFERROR(IF(VLOOKUP($C13,INDIRECT(O$5&"!$V$3:$AG$100"),11,0)>0,VLOOKUP($C13,INDIRECT(O$5&"!$V$3:$AG$100"),11,0),0),"") | ... BG15: =IFERROR(IF(VLOOKUP($C13,INDIRECT(BG$5&"!$V$3:$AG$100"),11,0)>0,VLOOKUP($C13,INDIRECT(BG$5&"!$V$3:$AG$100"),11,0),0),"")
B16: G | D16: =IF(C16="","",C16) | E16: =IF(B16="","",B16) -> G | F16: A | G16: =SUM(H16:BG16) -> 0 | H16: =IFERROR(IF(VLOOKUP($C16,INDIRECT(H$5&"!$V$3:$AG$100"),2,0)>0,1,0),"") | I16: =IFERROR(IF(VLOOKUP($C16,INDIRECT(I$5&"!$V$3:$AG$100"),2,0)>0,1,0),"") | J16: =IFERROR(IF(VLOOKUP($C16,INDIRECT(J$5&"!$V$3:$AG$100"),2,0)>0,1,0),"") | K16: =IFERROR(IF(VLOOKUP($C16,INDIRECT(K$5&"!$V$3:$AG$100"),2,0)>0,1,0),"") | L16: =IFERROR(IF(VLOOKUP($C16,INDIRECT(L$5&"!$V$3:$AG$100"),2,0)>0,1,0),"") | M16: =IFERROR(IF(VLOOKUP($C16,INDIRECT(M$5&"!$V$3:$AG$100"),2,0)>0,1,0),"") | N16: =IFERROR(IF(VLOOKUP($C16,INDIRECT(N$5&"!$V$3:$AG$100"),2,0)>0,1,0),"") | O16: =IFERROR(IF(VLOOKUP($C16,INDIRECT(O$5&"!$V$3:$AG$100"),2,0)>0,1,0),"") | ... BG16: =IFERROR(IF(VLOOKUP($C16,INDIRECT(BG$5&"!$V$3:$AG$100"),2,0)>0,1,0),"")
D17: =IF(C17="","",C17) | E17: =IF(B17="","",B17) | F17: G | G17: =SUM(H17:BG17) -> 0 | H17: =IFERROR(IF(VLOOKUP($C16,INDIRECT(H$5&"!$V$3:$AG$100"),12,0)>0,VLOOKUP($C16,INDIRECT(H$5&"!$V$3:$AG$100"),12,0),0),"") | I17: =IFERROR(IF(VLOOKUP($C16,INDIRECT(I$5&"!$V$3:$AG$100"),12,0)>0,VLOOKUP($C16,INDIRECT(I$5&"!$V$3:$AG$100"),12,0),0),"") | J17: =IFERROR(IF(VLOOKUP($C16,INDIRECT(J$5&"!$V$3:$AG$100"),12,0)>0,VLOOKUP($C16,INDIRECT(J$5&"!$V$3:$AG$100"),12,0),0),"") | K17: =IFERROR(IF(VLOOKUP($C16,INDIRECT(K$5&"!$V$3:$AG$100"),12,0)>0,VLOOKUP($C16,INDIRECT(K$5&"!$V$3:$AG$100"),12,0),0),"") | L17: =IFERROR(IF(VLOOKUP($C16,INDIRECT(L$5&"!$V$3:$AG$100"),12,0)>0,VLOOKUP($C16,INDIRECT(L$5&"!$V$3:$AG$100"),12,0),0),"") | M17: =IFERROR(IF(VLOOKUP($C16,INDIRECT(M$5&"!$V$3:$AG$100"),12,0)>0,VLOOKUP($C16,INDIRECT(M$5&"!$V$3:$AG$100"),12,0),0),"") | N17: =IFERROR(IF(VLOOKUP($C16,INDIRECT(N$5&"!$V$3:$AG$100"),12,0)>0,VLOOKUP($C16,INDIRECT(N$5&"!$V$3:$AG$100"),12,0),0),"") | O17: =IFERROR(IF(VLOOKUP($C16,INDIRECT(O$5&"!$V$3:$AG$100"),12,0)>0,VLOOKUP($C16,INDIRECT(O$5&"!$V$3:$AG$100"),12,0),0),"") | ... BG17: =IFERROR(IF(VLOOKUP($C16,INDIRECT(BG$5&"!$V$3:$AG$100"),12,0)>0,VLOOKUP($C16,INDIRECT(BG$5&"!$V$3:$AG$100"),12,0),0),"")
D18: =IF(C18="","",C18) | E18: =IF(B18="","",B18) | F18: P | G18: =SUM(H18:BG18) -> 0 | H18: =IFERROR(IF(VLOOKUP($C16,INDIRECT(H$5&"!$V$3:$AG$100"),11,0)>0,VLOOKUP($C16,INDIRECT(H$5&"!$V$3:$AG$100"),11,0),0),"") | I18: =IFERROR(IF(VLOOKUP($C16,INDIRECT(I$5&"!$V$3:$AG$100"),11,0)>0,VLOOKUP($C16,INDIRECT(I$5&"!$V$3:$AG$100"),11,0),0),"") | J18: =IFERROR(IF(VLOOKUP($C16,INDIRECT(J$5&"!$V$3:$AG$100"),11,0)>0,VLOOKUP($C16,INDIRECT(J$5&"!$V$3:$AG$100"),11,0),0),"") | K18: =IFERROR(IF(VLOOKUP($C16,INDIRECT(K$5&"!$V$3:$AG$100"),11,0)>0,VLOOKUP($C16,INDIRECT(K$5&"!$V$3:$AG$100"),11,0),0),"") | L18: =IFERROR(IF(VLOOKUP($C16,INDIRECT(L$5&"!$V$3:$AG$100"),11,0)>0,VLOOKUP($C16,INDIRECT(L$5&"!$V$3:$AG$100"),11,0),0),"") | M18: =IFERROR(IF(VLOOKUP($C16,INDIRECT(M$5&"!$V$3:$AG$100"),11,0)>0,VLOOKUP($C16,INDIRECT(M$5&"!$V$3:$AG$100"),11,0),0),"") | N18: =IFERROR(IF(VLOOKUP($C16,INDIRECT(N$5&"!$V$3:$AG$100"),11,0)>0,VLOOKUP($C16,INDIRECT(N$5&"!$V$3:$AG$100"),11,0),0),"") | O18: =IFERROR(IF(VLOOKUP($C16,INDIRECT(O$5&"!$V$3:$AG$100"),11,0)>0,VLOOKUP($C16,INDIRECT(O$5&"!$V$3:$AG$100"),11,0),0),"") | ... BG18: =IFERROR(IF(VLOOKUP($C16,INDIRECT(BG$5&"!$V$3:$AG$100"),11,0)>0,VLOOKUP($C16,INDIRECT(BG$5&"!$V$3:$AG$100"),11,0),0),"")
B19: Z | C19: Andre | D19: =IF(C19="","",C19) -> Andre | E19: =IF(B19="","",B19) -> Z | F19: A | G19: =SUM(H19:BG19) -> 28 | H19: =IFERROR(IF(VLOOKUP($C19,INDIRECT(H$5&"!$V$3:$AG$100"),2,0)>0,1,0),"") | I19: =IFERROR(IF(VLOOKUP($C19,INDIRECT(I$5&"!$V$3:$AG$100"),2,0)>0,1,0),"") -> 1 | J19: =IFERROR(IF(VLOOKUP($C19,INDIRECT(J$5&"!$V$3:$AG$100"),2,0)>0,1,0),"") -> 1 | K19: =IFERROR(IF(VLOOKUP($C19,INDIRECT(K$5&"!$V$3:$AG$100"),2,0)>0,1,0),"") -> 1 | L19: =IFERROR(IF(VLOOKUP($C19,INDIRECT(L$5&"!$V$3:$AG$100"),2,0)>0,1,0),"") | M19: =IFERROR(IF(VLOOKUP($C19,INDIRECT(M$5&"!$V$3:$AG$100"),2,0)>0,1,0),"") | N19: =IFERROR(IF(VLOOKUP($C19,INDIRECT(N$5&"!$V$3:$AG$100"),2,0)>0,1,0),"") -> 1 | O19: =IFERROR(IF(VLOOKUP($C19,INDIRECT(O$5&"!$V$3:$AG$100"),2,0)>0,1,0),"") -> 1 | ... BG19: =IFERROR(IF(VLOOKUP($C19,INDIRECT(BG$5&"!$V$3:$AG$100"),2,0)>0,1,0),"")
D20: =IF(C20="","",C20) | E20: =IF(B20="","",B20) | F20: G | G20: =SUM(H20:BG20) -> 2 | H20: =IFERROR(IF(VLOOKUP($C19,INDIRECT(H$5&"!$V$3:$AG$100"),12,0)>0,VLOOKUP($C19,INDIRECT(H$5&"!$V$3:$AG$100"),12,0),0),"") | I20: =IFERROR(IF(VLOOKUP($C19,INDIRECT(I$5&"!$V$3:$AG$100"),12,0)>0,VLOOKUP($C19,INDIRECT(I$5&"!$V$3:$AG$100"),12,0),0),"") -> 0 | J20: =IFERROR(IF(VLOOKUP($C19,INDIRECT(J$5&"!$V$3:$AG$100"),12,0)>0,VLOOKUP($C19,INDIRECT(J$5&"!$V$3:$AG$100"),12,0),0),"") -> 0 | K20: =IFERROR(IF(VLOOKUP($C19,INDIRECT(K$5&"!$V$3:$AG$100"),12,0)>0,VLOOKUP($C19,INDIRECT(K$5&"!$V$3:$AG$100"),12,0),0),"") -> 0 | L20: =IFERROR(IF(VLOOKUP($C19,INDIRECT(L$5&"!$V$3:$AG$100"),12,0)>0,VLOOKUP($C19,INDIRECT(L$5&"!$V$3:$AG$100"),12,0),0),"") | M20: =IFERROR(IF(VLOOKUP($C19,INDIRECT(M$5&"!$V$3:$AG$100"),12,0)>0,VLOOKUP($C19,INDIRECT(M$5&"!$V$3:$AG$100"),12,0),0),"") | N20: =IFERROR(IF(VLOOKUP($C19,INDIRECT(N$5&"!$V$3:$AG$100"),12,0)>0,VLOOKUP($C19,INDIRECT(N$5&"!$V$3:$AG$100"),12,0),0),"") -> 0 | O20: =IFERROR(IF(VLOOKUP($C19,INDIRECT(O$5&"!$V$3:$AG$100"),12,0)>0,VLOOKUP($C19,INDIRECT(O$5&"!$V$3:$AG$100"),12,0),0),"") -> 0 | ... BG20: =IFERROR(IF(VLOOKUP($C19,INDIRECT(BG$5&"!$V$3:$AG$100"),12,0)>0,VLOOKUP($C19,INDIRECT(BG$5&"!$V$3:$AG$100"),12,0),0),"")
D21: =IF(C21="","",C21) | E21: =IF(B21="","",B21) | F21: P | G21: =SUM(H21:BG21) -> 214 | H21: =IFERROR(IF(VLOOKUP($C19,INDIRECT(H$5&"!$V$3:$AG$100"),11,0)>0,VLOOKUP($C19,INDIRECT(H$5&"!$V$3:$AG$100"),11,0),0),"") | I21: =IFERROR(IF(VLOOKUP($C19,INDIRECT(I$5&"!$V$3:$AG$100"),11,0)>0,VLOOKUP($C19,INDIRECT(I$5&"!$V$3:$AG$100"),11,0),0),"") -> 6 | J21: =IFERROR(IF(VLOOKUP($C19,INDIRECT(J$5&"!$V$3:$AG$100"),11,0)>0,VLOOKUP($C19,INDIRECT(J$5&"!$V$3:$AG$100"),11,0),0),"") -> 3 | K21: =IFERROR(IF(VLOOKUP($C19,INDIRECT(K$5&"!$V$3:$AG$100"),11,0)>0,VLOOKUP($C19,INDIRECT(K$5&"!$V$3:$AG$100"),11,0),0),"") -> 8 | L21: =IFERROR(IF(VLOOKUP($C19,INDIRECT(L$5&"!$V$3:$AG$100"),11,0)>0,VLOOKUP($C19,INDIRECT(L$5&"!$V$3:$AG$100"),11,0),0),"") | M21: =IFERROR(IF(VLOOKUP($C19,INDIRECT(M$5&"!$V$3:$AG$100"),11,0)>0,VLOOKUP($C19,INDIRECT(M$5&"!$V$3:$AG$100"),11,0),0),"") | N21: =IFERROR(IF(VLOOKUP($C19,INDIRECT(N$5&"!$V$3:$AG$100"),11,0)>0,VLOOKUP($C19,INDIRECT(N$5&"!$V$3:$AG$100"),11,0),0),"") -> 3 | O21: =IFERROR(IF(VLOOKUP($C19,INDIRECT(O$5&"!$V$3:$AG$100"),11,0)>0,VLOOKUP($C19,INDIRECT(O$5&"!$V$3:$AG$100"),11,0),0),"") -> 11 | ... BG21: =IFERROR(IF(VLOOKUP($C19,INDIRECT(BG$5&"!$V$3:$AG$100"),11,0)>0,VLOOKUP($C19,INDIRECT(BG$5&"!$V$3:$AG$100"),11,0),0),"")
B22: Z | C22: Fernando | D22: =IF(C22="","",C22) -> Fernando | E22: =IF(B22="","",B22) -> Z | F22: A | G22: =SUM(H22:BG22) -> 23 | H22: =IFERROR(IF(VLOOKUP($C22,INDIRECT(H$5&"!$V$3:$AG$100"),2,0)>0,1,0),"") | I22: =IFERROR(IF(VLOOKUP($C22,INDIRECT(I$5&"!$V$3:$AG$100"),2,0)>0,1,0),"") -> 1 | J22: =IFERROR(IF(VLOOKUP($C22,INDIRECT(J$5&"!$V$3:$AG$100"),2,0)>0,1,0),"") -> 1 | K22: =IFERROR(IF(VLOOKUP($C22,INDIRECT(K$5&"!$V$3:$AG$100"),2,0)>0,1,0),"") | L22: =IFERROR(IF(VLOOKUP($C22,INDIRECT(L$5&"!$V$3:$AG$100"),2,0)>0,1,0),"") | M22: =IFERROR(IF(VLOOKUP($C22,INDIRECT(M$5&"!$V$3:$AG$100"),2,0)>0,1,0),"") | N22: =IFERROR(IF(VLOOKUP($C22,INDIRECT(N$5&"!$V$3:$AG$100"),2,0)>0,1,0),"") -> 1 | O22: =IFERROR(IF(VLOOKUP($C22,INDIRECT(O$5&"!$V$3:$AG$100"),2,0)>0,1,0),"") -> 1 | ... BG22: =IFERROR(IF(VLOOKUP($C22,INDIRECT(BG$5&"!$V$3:$AG$100"),2,0)>0,1,0),"")
D23: =IF(C23="","",C23) | E23: =IF(B23="","",B23) | F23: G | G23: =SUM(H23:BG23) -> 13 | H23: =IFERROR(IF(VLOOKUP($C22,INDIRECT(H$5&"!$V$3:$AG$100"),12,0)>0,VLOOKUP($C22,INDIRECT(H$5&"!$V$3:$AG$100"),12,0),0),"") | I23: =IFERROR(IF(VLOOKUP($C22,INDIRECT(I$5&"!$V$3:$AG$100"),12,0)>0,VLOOKUP($C22,INDIRECT(I$5&"!$V$3:$AG$100"),12,0),0),"") -> 0 | J23: =IFERROR(IF(VLOOKUP($C22,INDIRECT(J$5&"!$V$3:$AG$100"),12,0)>0,VLOOKUP($C22,INDIRECT(J$5&"!$V$3:$AG$100"),12,0),0),"") -> 1 | K23: =IFERROR(IF(VLOOKUP($C22,INDIRECT(K$5&"!$V$3:$AG$100"),12,0)>0,VLOOKUP($C22,INDIRECT(K$5&"!$V$3:$AG$100"),12,0),0),"") | L23: =IFERROR(IF(VLOOKUP($C22,INDIRECT(L$5&"!$V$3:$AG$100"),12,0)>0,VLOOKUP($C22,INDIRECT(L$5&"!$V$3:$AG$100"),12,0),0),"") | M23: =IFERROR(IF(VLOOKUP($C22,INDIRECT(M$5&"!$V$3:$AG$100"),12,0)>0,VLOOKUP($C22,INDIRECT(M$5&"!$V$3:$AG$100"),12,0),0),"") | N23: =IFERROR(IF(VLOOKUP($C22,INDIRECT(N$5&"!$V$3:$AG$100"),12,0)>0,VLOOKUP($C22,INDIRECT(N$5&"!$V$3:$AG$100"),12,0),0),"") -> 0 | O23: =IFERROR(IF(VLOOKUP($C22,INDIRECT(O$5&"!$V$3:$AG$100"),12,0)>0,VLOOKUP($C22,INDIRECT(O$5&"!$V$3:$AG$100"),12,0),0),"") -> 0 | ... BG23: =IFERROR(IF(VLOOKUP($C22,INDIRECT(BG$5&"!$V$3:$AG$100"),12,0)>0,VLOOKUP($C22,INDIRECT(BG$5&"!$V$3:$AG$100"),12,0),0),"")
D24: =IF(C24="","",C24) | E24: =IF(B24="","",B24) | F24: P | G24: =SUM(H24:BG24) -> 161 | H24: =IFERROR(IF(VLOOKUP($C22,INDIRECT(H$5&"!$V$3:$AG$100"),11,0)>0,VLOOKUP($C22,INDIRECT(H$5&"!$V$3:$AG$100"),11,0),0),"") | I24: =IFERROR(IF(VLOOKUP($C22,INDIRECT(I$5&"!$V$3:$AG$100"),11,0)>0,VLOOKUP($C22,INDIRECT(I$5&"!$V$3:$AG$100"),11,0),0),"") -> 11 | J24: =IFERROR(IF(VLOOKUP($C22,INDIRECT(J$5&"!$V$3:$AG$100"),11,0)>0,VLOOKUP($C22,INDIRECT(J$5&"!$V$3:$AG$100"),11,0),0),"") -> 7 | K24: =IFERROR(IF(VLOOKUP($C22,INDIRECT(K$5&"!$V$3:$AG$100"),11,0)>0,VLOOKUP($C22,INDIRECT(K$5&"!$V$3:$AG$100"),11,0),0),"") | L24: =IFERROR(IF(VLOOKUP($C22,INDIRECT(L$5&"!$V$3:$AG$100"),11,0)>0,VLOOKUP($C22,INDIRECT(L$5&"!$V$3:$AG$100"),11,0),0),"") | M24: =IFERROR(IF(VLOOKUP($C22,INDIRECT(M$5&"!$V$3:$AG$100"),11,0)>0,VLOOKUP($C22,INDIRECT(M$5&"!$V$3:$AG$100"),11,0),0),"") | N24: =IFERROR(IF(VLOOKUP($C22,INDIRECT(N$5&"!$V$3:$AG$100"),11,0)>0,VLOOKUP($C22,INDIRECT(N$5&"!$V$3:$AG$100"),11,0),0),"") -> 6 | O24: =IFERROR(IF(VLOOKUP($C22,INDIRECT(O$5&"!$V$3:$AG$100"),11,0)>0,VLOOKUP($C22,INDIRECT(O$5&"!$V$3:$AG$100"),11,0),0),"") -> 2 | ... BG24: =IFERROR(IF(VLOOKUP($C22,INDIRECT(BG$5&"!$V$3:$AG$100"),11,0)>0,VLOOKUP($C22,INDIRECT(BG$5&"!$V$3:$AG$100"),11,0),0),"")
B25: Z | C25: Kike | D25: =IF(C25="","",C25) -> Kike | E25: =IF(B25="","",B25) -> Z | F25: A | G25: =SUM(H25:BG25) -> 15 | H25: =IFERROR(IF(VLOOKUP($C25,INDIRECT(H$5&"!$V$3:$AG$100"),2,0)>0,1,0),"") | I25: =IFERROR(IF(VLOOKUP($C25,INDIRECT(I$5&"!$V$3:$AG$100"),2,0)>0,1,0),"") -> 1 | J25: =IFERROR(IF(VLOOKUP($C25,INDIRECT(J$5&"!$V$3:$AG$100"),2,0)>0,1,0),"") | K25: =IFERROR(IF(VLOOKUP($C25,INDIRECT(K$5&"!$V$3:$AG$100"),2,0)>0,1,0),"") | L25: =IFERROR(IF(VLOOKUP($C25,INDIRECT(L$5&"!$V$3:$AG$100"),2,0)>0,1,0),"") | M25: =IFERROR(IF(VLOOKUP($C25,INDIRECT(M$5&"!$V$3:$AG$100"),2,0)>0,1,0),"") | N25: =IFERROR(IF(VLOOKUP($C25,INDIRECT(N$5&"!$V$3:$AG$100"),2,0)>0,1,0),"") -> 1 | O25: =IFERROR(IF(VLOOKUP($C25,INDIRECT(O$5&"!$V$3:$AG$100"),2,0)>0,1,0),"") | ... BG25: =IFERROR(IF(VLOOKUP($C25,INDIRECT(BG$5&"!$V$3:$AG$100"),2,0)>0,1,0),"")
D26: =IF(C26="","",C26) | E26: =IF(B26="","",B26) | F26: G | G26: =SUM(H26:BG26) -> 1 | H26: =IFERROR(IF(VLOOKUP($C25,INDIRECT(H$5&"!$V$3:$AG$100"),12,0)>0,VLOOKUP($C25,INDIRECT(H$5&"!$V$3:$AG$100"),12,0),0),"") | I26: =IFERROR(IF(VLOOKUP($C25,INDIRECT(I$5&"!$V$3:$AG$100"),12,0)>0,VLOOKUP($C25,INDIRECT(I$5&"!$V$3:$AG$100"),12,0),0),"") -> 0 | J26: =IFERROR(IF(VLOOKUP($C25,INDIRECT(J$5&"!$V$3:$AG$100"),12,0)>0,VLOOKUP($C25,INDIRECT(J$5&"!$V$3:$AG$100"),12,0),0),"") | K26: =IFERROR(IF(VLOOKUP($C25,INDIRECT(K$5&"!$V$3:$AG$100"),12,0)>0,VLOOKUP($C25,INDIRECT(K$5&"!$V$3:$AG$100"),12,0),0),"") | L26: =IFERROR(IF(VLOOKUP($C25,INDIRECT(L$5&"!$V$3:$AG$100"),12,0)>0,VLOOKUP($C25,INDIRECT(L$5&"!$V$3:$AG$100"),12,0),0),"") | M26: =IFERROR(IF(VLOOKUP($C25,INDIRECT(M$5&"!$V$3:$AG$100"),12,0)>0,VLOOKUP($C25,INDIRECT(M$5&"!$V$3:$AG$100"),12,0),0),"") | N26: =IFERROR(IF(VLOOKUP($C25,INDIRECT(N$5&"!$V$3:$AG$100"),12,0)>0,VLOOKUP($C25,INDIRECT(N$5&"!$V$3:$AG$100"),12,0),0),"") -> 0 | O26: =IFERROR(IF(VLOOKUP($C25,INDIRECT(O$5&"!$V$3:$AG$100"),12,0)>0,VLOOKUP($C25,INDIRECT(O$5&"!$V$3:$AG$100"),12,0),0),"") | ... BG26: =IFERROR(IF(VLOOKUP($C25,INDIRECT(BG$5&"!$V$3:$AG$100"),12,0)>0,VLOOKUP($C25,INDIRECT(BG$5&"!$V$3:$AG$100"),12,0),0),"")
D27: =IF(C27="","",C27) | E27: =IF(B27="","",B27) | F27: P | G27: =SUM(H27:BG27) -> 80 | H27: =IFERROR(IF(VLOOKUP($C25,INDIRECT(H$5&"!$V$3:$AG$100"),11,0)>0,VLOOKUP($C25,INDIRECT(H$5&"!$V$3:$AG$100"),11,0),0),"") | I27: =IFERROR(IF(VLOOKUP($C25,INDIRECT(I$5&"!$V$3:$AG$100"),11,0)>0,VLOOKUP($C25,INDIRECT(I$5&"!$V$3:$AG$100"),11,0),0),"") -> 0 | J27: =IFERROR(IF(VLOOKUP($C25,INDIRECT(J$5&"!$V$3:$AG$100"),11,0)>0,VLOOKUP($C25,INDIRECT(J$5&"!$V$3:$AG$100"),11,0),0),"") | K27: =IFERROR(IF(VLOOKUP($C25,INDIRECT(K$5&"!$V$3:$AG$100"),11,0)>0,VLOOKUP($C25,INDIRECT(K$5&"!$V$3:$AG$100"),11,0),0),"") | L27: =IFERROR(IF(VLOOKUP($C25,INDIRECT(L$5&"!$V$3:$AG$100"),11,0)>0,VLOOKUP($C25,INDIRECT(L$5&"!$V$3:$AG$100"),11,0),0),"") | M27: =IFERROR(IF(VLOOKUP($C25,INDIRECT(M$5&"!$V$3:$AG$100"),11,0)>0,VLOOKUP($C25,INDIRECT(M$5&"!$V$3:$AG$100"),11,0),0),"") | N27: =IFERROR(IF(VLOOKUP($C25,INDIRECT(N$5&"!$V$3:$AG$100"),11,0)>0,VLOOKUP($C25,INDIRECT(N$5&"!$V$3:$AG$100"),11,0),0),"") -> 3 | O27: =IFERROR(IF(VLOOKUP($C25,INDIRECT(O$5&"!$V$3:$AG$100"),11,0)>0,VLOOKUP($C25,INDIRECT(O$5&"!$V$3:$AG$100"),11,0),0),"") | ... BG27: =IFERROR(IF(VLOOKUP($C25,INDIRECT(BG$5&"!$V$3:$AG$100"),11,0)>0,VLOOKUP($C25,INDIRECT(BG$5&"!$V$3:$AG$100"),11,0),0),"")
B28: Z | C28: Rodrigo | D28: =IF(C28="","",C28) -> Rodrigo | E28: =IF(B28="","",B28) -> Z | F28: A | G28: =SUM(H28:BG28) -> 1 | H28: =IFERROR(IF(VLOOKUP($C28,INDIRECT(H$5&"!$V$3:$AG$100"),2,0)>0,1,0),"") | I28: =IFERROR(IF(VLOOKUP($C28,INDIRECT(I$5&"!$V$3:$AG$100"),2,0)>0,1,0),"") | J28: =IFERROR(IF(VLOOKUP($C28,INDIRECT(J$5&"!$V$3:$AG$100"),2,0)>0,1,0),"") | K28: =IFERROR(IF(VLOOKUP($C28,INDIRECT(K$5&"!$V$3:$AG$100"),2,0)>0,1,0),"") | L28: =IFERROR(IF(VLOOKUP($C28,INDIRECT(L$5&"!$V$3:$AG$100"),2,0)>0,1,0),"") | M28: =IFERROR(IF(VLOOKUP($C28,INDIRECT(M$5&"!$V$3:$AG$100"),2,0)>0,1,0),"") | N28: =IFERROR(IF(VLOOKUP($C28,INDIRECT(N$5&"!$V$3:$AG$100"),2,0)>0,1,0),"") | O28: =IFERROR(IF(VLOOKUP($C28,INDIRECT(O$5&"!$V$3:$AG$100"),2,0)>0,1,0),"") | ... BG28: =IFERROR(IF(VLOOKUP($C28,INDIRECT(BG$5&"!$V$3:$AG$100"),2,0)>0,1,0),"")
D29: =IF(C29="","",C29) | E29: =IF(B29="","",B29) | F29: G | G29: =SUM(H29:BG29) -> 1 | H29: =IFERROR(IF(VLOOKUP($C28,INDIRECT(H$5&"!$V$3:$AG$100"),12,0)>0,VLOOKUP($C28,INDIRECT(H$5&"!$V$3:$AG$100"),12,0),0),"") | I29: =IFERROR(IF(VLOOKUP($C28,INDIRECT(I$5&"!$V$3:$AG$100"),12,0)>0,VLOOKUP($C28,INDIRECT(I$5&"!$V$3:$AG$100"),12,0),0),"") | J29: =IFERROR(IF(VLOOKUP($C28,INDIRECT(J$5&"!$V$3:$AG$100"),12,0)>0,VLOOKUP($C28,INDIRECT(J$5&"!$V$3:$AG$100"),12,0),0),"") | K29: =IFERROR(IF(VLOOKUP($C28,INDIRECT(K$5&"!$V$3:$AG$100"),12,0)>0,VLOOKUP($C28,INDIRECT(K$5&"!$V$3:$AG$100"),12,0),0),"") | L29: =IFERROR(IF(VLOOKUP($C28,INDIRECT(L$5&"!$V$3:$AG$100"),12,0)>0,VLOOKUP($C28,INDIRECT(L$5&"!$V$3:$AG$100"),12,0),0),"") | M29: =IFERROR(IF(VLOOKUP($C28,INDIRECT(M$5&"!$V$3:$AG$100"),12,0)>0,VLOOKUP($C28,INDIRECT(M$5&"!$V$3:$AG$100"),12,0),0),"") | N29: =IFERROR(IF(VLOOKUP($C28,INDIRECT(N$5&"!$V$3:$AG$100"),12,0)>0,VLOOKUP($C28,INDIRECT(N$5&"!$V$3:$AG$100"),12,0),0),"") | O29: =IFERROR(IF(VLOOKUP($C28,INDIRECT(O$5&"!$V$3:$AG$100"),12,0)>0,VLOOKUP($C28,INDIRECT(O$5&"!$V$3:$AG$100"),12,0),0),"") | ... BG29: =IFERROR(IF(VLOOKUP($C28,INDIRECT(BG$5&"!$V$3:$AG$100"),12,0)>0,VLOOKUP($C28,INDIRECT(BG$5&"!$V$3:$AG$100"),12,0),0),"")
D30: =IF(C30="","",C30) | E30: =IF(B30="","",B30) | F30: P | G30: =SUM(H30:BG30) -> 9 | H30: =IFERROR(IF(VLOOKUP($C28,INDIRECT(H$5&"!$V$3:$AG$100"),11,0)>0,VLOOKUP($C28,INDIRECT(H$5&"!$V$3:$AG$100"),11,0),0),"") | I30: =IFERROR(IF(VLOOKUP($C28,INDIRECT(I$5&"!$V$3:$AG$100"),11,0)>0,VLOOKUP($C28,INDIRECT(I$5&"!$V$3:$AG$100"),11,0),0),"") | J30: =IFERROR(IF(VLOOKUP($C28,INDIRECT(J$5&"!$V$3:$AG$100"),11,0)>0,VLOOKUP($C28,INDIRECT(J$5&"!$V$3:$AG$100"),11,0),0),"") | K30: =IFERROR(IF(VLOOKUP($C28,INDIRECT(K$5&"!$V$3:$AG$100"),11,0)>0,VLOOKUP($C28,INDIRECT(K$5&"!$V$3:$AG$100"),11,0),0),"") | L30: =IFERROR(IF(VLOOKUP($C28,INDIRECT(L$5&"!$V$3:$AG$100"),11,0)>0,VLOOKUP($C28,INDIRECT(L$5&"!$V$3:$AG$100"),11,0),0),"") | M30: =IFERROR(IF(VLOOKUP($C28,INDIRECT(M$5&"!$V$3:$AG$100"),11,0)>0,VLOOKUP($C28,INDIRECT(M$5&"!$V$3:$AG$100"),11,0),0),"") | N30: =IFERROR(IF(VLOOKUP($C28,INDIRECT(N$5&"!$V$3:$AG$100"),11,0)>0,VLOOKUP($C28,INDIRECT(N$5&"!$V$3:$AG$100"),11,0),0),"") | O30: =IFERROR(IF(VLOOKUP($C28,INDIRECT(O$5&"!$V$3:$AG$100"),11,0)>0,VLOOKUP($C28,INDIRECT(O$5&"!$V$3:$AG$100"),11,0),0),"") | ... BG30: =IFERROR(IF(VLOOKUP($C28,INDIRECT(BG$5&"!$V$3:$AG$100"),11,0)>0,VLOOKUP($C28,INDIRECT(BG$5&"!$V$3:$AG$100"),11,0),0),"")
B31: Z | D31: =IF(C31="","",C31) | E31: =IF(B31="","",B31) -> Z | F31: A | G31: =SUM(H31:BG31) -> 0 | H31: =IFERROR(IF(VLOOKUP($C31,INDIRECT(H$5&"!$V$3:$AG$100"),2,0)>0,1,0),"") | I31: =IFERROR(IF(VLOOKUP($C31,INDIRECT(I$5&"!$V$3:$AG$100"),2,0)>0,1,0),"") | J31: =IFERROR(IF(VLOOKUP($C31,INDIRECT(J$5&"!$V$3:$AG$100"),2,0)>0,1,0),"") | K31: =IFERROR(IF(VLOOKUP($C31,INDIRECT(K$5&"!$V$3:$AG$100"),2,0)>0,1,0),"") | L31: =IFERROR(IF(VLOOKUP($C31,INDIRECT(L$5&"!$V$3:$AG$100"),2,0)>0,1,0),"") | M31: =IFERROR(IF(VLOOKUP($C31,INDIRECT(M$5&"!$V$3:$AG$100"),2,0)>0,1,0),"") | N31: =IFERROR(IF(VLOOKUP($C31,INDIRECT(N$5&"!$V$3:$AG$100"),2,0)>0,1,0),"") | O31: =IFERROR(IF(VLOOKUP($C31,INDIRECT(O$5&"!$V$3:$AG$100"),2,0)>0,1,0),"") | ... BG31: =IFERROR(IF(VLOOKUP($C31,INDIRECT(BG$5&"!$V$3:$AG$100"),2,0)>0,1,0),"")
D32: =IF(C32="","",C32) | E32: =IF(B32="","",B32) | F32: G | G32: =SUM(H32:BG32) -> 0 | H32: =IFERROR(IF(VLOOKUP($C31,INDIRECT(H$5&"!$V$3:$AG$100"),12,0)>0,VLOOKUP($C31,INDIRECT(H$5&"!$V$3:$AG$100"),12,0),0),"") | I32: =IFERROR(IF(VLOOKUP($C31,INDIRECT(I$5&"!$V$3:$AG$100"),12,0)>0,VLOOKUP($C31,INDIRECT(I$5&"!$V$3:$AG$100"),12,0),0),"") | J32: =IFERROR(IF(VLOOKUP($C31,INDIRECT(J$5&"!$V$3:$AG$100"),12,0)>0,VLOOKUP($C31,INDIRECT(J$5&"!$V$3:$AG$100"),12,0),0),"") | K32: =IFERROR(IF(VLOOKUP($C31,INDIRECT(K$5&"!$V$3:$AG$100"),12,0)>0,VLOOKUP($C31,INDIRECT(K$5&"!$V$3:$AG$100"),12,0),0),"") | L32: =IFERROR(IF(VLOOKUP($C31,INDIRECT(L$5&"!$V$3:$AG$100"),12,0)>0,VLOOKUP($C31,INDIRECT(L$5&"!$V$3:$AG$100"),12,0),0),"") | M32: =IFERROR(IF(VLOOKUP($C31,INDIRECT(M$5&"!$V$3:$AG$100"),12,0)>0,VLOOKUP($C31,INDIRECT(M$5&"!$V$3:$AG$100"),12,0),0),"") | N32: =IFERROR(IF(VLOOKUP($C31,INDIRECT(N$5&"!$V$3:$AG$100"),12,0)>0,VLOOKUP($C31,INDIRECT(N$5&"!$V$3:$AG$100"),12,0),0),"") | O32: =IFERROR(IF(VLOOKUP($C31,INDIRECT(O$5&"!$V$3:$AG$100"),12,0)>0,VLOOKUP($C31,INDIRECT(O$5&"!$V$3:$AG$100"),12,0),0),"") | ... BG32: =IFERROR(IF(VLOOKUP($C31,INDIRECT(BG$5&"!$V$3:$AG$100"),12,0)>0,VLOOKUP($C31,INDIRECT(BG$5&"!$V$3:$AG$100"),12,0),0),"")
D33: =IF(C33="","",C33) | E33: =IF(B33="","",B33) | F33: P | G33: =SUM(H33:BG33) -> 0 | H33: =IFERROR(IF(VLOOKUP($C31,INDIRECT(H$5&"!$V$3:$AG$100"),11,0)>0,VLOOKUP($C31,INDIRECT(H$5&"!$V$3:$AG$100"),11,0),0),"") | I33: =IFERROR(IF(VLOOKUP($C31,INDIRECT(I$5&"!$V$3:$AG$100"),11,0)>0,VLOOKUP($C31,INDIRECT(I$5&"!$V$3:$AG$100"),11,0),0),"") | J33: =IFERROR(IF(VLOOKUP($C31,INDIRECT(J$5&"!$V$3:$AG$100"),11,0)>0,VLOOKUP($C31,INDIRECT(J$5&"!$V$3:$AG$100"),11,0),0),"") | K33: =IFERROR(IF(VLOOKUP($C31,INDIRECT(K$5&"!$V$3:$AG$100"),11,0)>0,VLOOKUP($C31,INDIRECT(K$5&"!$V$3:$AG$100"),11,0),0),"") | L33: =IFERROR(IF(VLOOKUP($C31,INDIRECT(L$5&"!$V$3:$AG$100"),11,0)>0,VLOOKUP($C31,INDIRECT(L$5&"!$V$3:$AG$100"),11,0),0),"") | M33: =IFERROR(IF(VLOOKUP($C31,INDIRECT(M$5&"!$V$3:$AG$100"),11,0)>0,VLOOKUP($C31,INDIRECT(M$5&"!$V$3:$AG$100"),11,0),0),"") | N33: =IFERROR(IF(VLOOKUP($C31,INDIRECT(N$5&"!$V$3:$AG$100"),11,0)>0,VLOOKUP($C31,INDIRECT(N$5&"!$V$3:$AG$100"),11,0),0),"") | O33: =IFERROR(IF(VLOOKUP($C31,INDIRECT(O$5&"!$V$3:$AG$100"),11,0)>0,VLOOKUP($C31,INDIRECT(O$5&"!$V$3:$AG$100"),11,0),0),"") | ... BG33: =IFERROR(IF(VLOOKUP($C31,INDIRECT(BG$5&"!$V$3:$AG$100"),11,0)>0,VLOOKUP($C31,INDIRECT(BG$5&"!$V$3:$AG$100"),11,0),0),"")
B34: Z | D34: =IF(C34="","",C34) | E34: =IF(B34="","",B34) -> Z | F34: A | G34: =SUM(H34:BG34) -> 0 | H34: =IFERROR(IF(VLOOKUP($C34,INDIRECT(H$5&"!$V$3:$AG$100"),2,0)>0,1,0),"") | I34: =IFERROR(IF(VLOOKUP($C34,INDIRECT(I$5&"!$V$3:$AG$100"),2,0)>0,1,0),"") | J34: =IFERROR(IF(VLOOKUP($C34,INDIRECT(J$5&"!$V$3:$AG$100"),2,0)>0,1,0),"") | K34: =IFERROR(IF(VLOOKUP($C34,INDIRECT(K$5&"!$V$3:$AG$100"),2,0)>0,1,0),"") | L34: =IFERROR(IF(VLOOKUP($C34,INDIRECT(L$5&"!$V$3:$AG$100"),2,0)>0,1,0),"") | M34: =IFERROR(IF(VLOOKUP($C34,INDIRECT(M$5&"!$V$3:$AG$100"),2,0)>0,1,0),"") | N34: =IFERROR(IF(VLOOKUP($C34,INDIRECT(N$5&"!$V$3:$AG$100"),2,0)>0,1,0),"") | O34: =IFERROR(IF(VLOOKUP($C34,INDIRECT(O$5&"!$V$3:$AG$100"),2,0)>0,1,0),"") | ... BG34: =IFERROR(IF(VLOOKUP($C34,INDIRECT(BG$5&"!$V$3:$AG$100"),2,0)>0,1,0),"")
D35: =IF(C35="","",C35) | E35: =IF(B35="","",B35) | F35: G | G35: =SUM(H35:BG35) -> 0 | H35: =IFERROR(IF(VLOOKUP($C34,INDIRECT(H$5&"!$V$3:$AG$100"),12,0)>0,VLOOKUP($C34,INDIRECT(H$5&"!$V$3:$AG$100"),12,0),0),"") | I35: =IFERROR(IF(VLOOKUP($C34,INDIRECT(I$5&"!$V$3:$AG$100"),12,0)>0,VLOOKUP($C34,INDIRECT(I$5&"!$V$3:$AG$100"),12,0),0),"") | J35: =IFERROR(IF(VLOOKUP($C34,INDIRECT(J$5&"!$V$3:$AG$100"),12,0)>0,VLOOKUP($C34,INDIRECT(J$5&"!$V$3:$AG$100"),12,0),0),"") | K35: =IFERROR(IF(VLOOKUP($C34,INDIRECT(K$5&"!$V$3:$AG$100"),12,0)>0,VLOOKUP($C34,INDIRECT(K$5&"!$V$3:$AG$100"),12,0),0),"") | L35: =IFERROR(IF(VLOOKUP($C34,INDIRECT(L$5&"!$V$3:$AG$100"),12,0)>0,VLOOKUP($C34,INDIRECT(L$5&"!$V$3:$AG$100"),12,0),0),"") | M35: =IFERROR(IF(VLOOKUP($C34,INDIRECT(M$5&"!$V$3:$AG$100"),12,0)>0,VLOOKUP($C34,INDIRECT(M$5&"!$V$3:$AG$100"),12,0),0),"") | N35: =IFERROR(IF(VLOOKUP($C34,INDIRECT(N$5&"!$V$3:$AG$100"),12,0)>0,VLOOKUP($C34,INDIRECT(N$5&"!$V$3:$AG$100"),12,0),0),"") | O35: =IFERROR(IF(VLOOKUP($C34,INDIRECT(O$5&"!$V$3:$AG$100"),12,0)>0,VLOOKUP($C34,INDIRECT(O$5&"!$V$3:$AG$100"),12,0),0),"") | ... BG35: =IFERROR(IF(VLOOKUP($C34,INDIRECT(BG$5&"!$V$3:$AG$100"),12,0)>0,VLOOKUP($C34,INDIRECT(BG$5&"!$V$3:$AG$100"),12,0),0),"")
D36: =IF(C36="","",C36) | E36: =IF(B36="","",B36) | F36: P | G36: =SUM(H36:BG36) -> 0 | H36: =IFERROR(IF(VLOOKUP($C34,INDIRECT(H$5&"!$V$3:$AG$100"),11,0)>0,VLOOKUP($C34,INDIRECT(H$5&"!$V$3:$AG$100"),11,0),0),"") | I36: =IFERROR(IF(VLOOKUP($C34,INDIRECT(I$5&"!$V$3:$AG$100"),11,0)>0,VLOOKUP($C34,INDIRECT(I$5&"!$V$3:$AG$100"),11,0),0),"") | J36: =IFERROR(IF(VLOOKUP($C34,INDIRECT(J$5&"!$V$3:$AG$100"),11,0)>0,VLOOKUP($C34,INDIRECT(J$5&"!$V$3:$AG$100"),11,0),0),"") | K36: =IFERROR(IF(VLOOKUP($C34,INDIRECT(K$5&"!$V$3:$AG$100"),11,0)>0,VLOOKUP($C34,INDIRECT(K$5&"!$V$3:$AG$100"),11,0),0),"") | L36: =IFERROR(IF(VLOOKUP($C34,INDIRECT(L$5&"!$V$3:$AG$100"),11,0)>0,VLOOKUP($C34,INDIRECT(L$5&"!$V$3:$AG$100"),11,0),0),"") | M36: =IFERROR(IF(VLOOKUP($C34,INDIRECT(M$5&"!$V$3:$AG$100"),11,0)>0,VLOOKUP($C34,INDIRECT(M$5&"!$V$3:$AG$100"),11,0),0),"") | N36: =IFERROR(IF(VLOOKUP($C34,INDIRECT(N$5&"!$V$3:$AG$100"),11,0)>0,VLOOKUP($C34,INDIRECT(N$5&"!$V$3:$AG$100"),11,0),0),"") | O36: =IFERROR(IF(VLOOKUP($C34,INDIRECT(O$5&"!$V$3:$AG$100"),11,0)>0,VLOOKUP($C34,INDIRECT(O$5&"!$V$3:$AG$100"),11,0),0),"") | ... BG36: =IFERROR(IF(VLOOKUP($C34,INDIRECT(BG$5&"!$V$3:$AG$100"),11,0)>0,VLOOKUP($C34,INDIRECT(BG$5&"!$V$3:$AG$100"),11,0),0),"")
B37: L | D37: =IF(C37="","",C37) | E37: =IF(B37="","",B37) -> L | F37: A | G37: =SUM(H37:BG37) -> 0 | H37: =IFERROR(IF(VLOOKUP($C37,INDIRECT(H$5&"!$V$3:$AG$100"),2,0)>0,1,0),"") | I37: =IFERROR(IF(VLOOKUP($C37,INDIRECT(I$5&"!$V$3:$AG$100"),2,0)>0,1,0),"") | J37: =IFERROR(IF(VLOOKUP($C37,INDIRECT(J$5&"!$V$3:$AG$100"),2,0)>0,1,0),"") | K37: =IFERROR(IF(VLOOKUP($C37,INDIRECT(K$5&"!$V$3:$AG$100"),2,0)>0,1,0),"") | L37: =IFERROR(IF(VLOOKUP($C37,INDIRECT(L$5&"!$V$3:$AG$100"),2,0)>0,1,0),"") | M37: =IFERROR(IF(VLOOKUP($C37,INDIRECT(M$5&"!$V$3:$AG$100"),2,0)>0,1,0),"") | N37: =IFERROR(IF(VLOOKUP($C37,INDIRECT(N$5&"!$V$3:$AG$100"),2,0)>0,1,0),"") | O37: =IFERROR(IF(VLOOKUP($C37,INDIRECT(O$5&"!$V$3:$AG$100"),2,0)>0,1,0),"") | ... BG37: =IFERROR(IF(VLOOKUP($C37,INDIRECT(BG$5&"!$V$3:$AG$100"),2,0)>0,1,0),"")
D38: =IF(C38="","",C38) | E38: =IF(B38="","",B38) | F38: G | G38: =SUM(H38:BG38) -> 0 | H38: =IFERROR(IF(VLOOKUP($C37,INDIRECT(H$5&"!$V$3:$AG$100"),12,0)>0,VLOOKUP($C37,INDIRECT(H$5&"!$V$3:$AG$100"),12,0),0),"") | I38: =IFERROR(IF(VLOOKUP($C37,INDIRECT(I$5&"!$V$3:$AG$100"),12,0)>0,VLOOKUP($C37,INDIRECT(I$5&"!$V$3:$AG$100"),12,0),0),"") | J38: =IFERROR(IF(VLOOKUP($C37,INDIRECT(J$5&"!$V$3:$AG$100"),12,0)>0,VLOOKUP($C37,INDIRECT(J$5&"!$V$3:$AG$100"),12,0),0),"") | K38: =IFERROR(IF(VLOOKUP($C37,INDIRECT(K$5&"!$V$3:$AG$100"),12,0)>0,VLOOKUP($C37,INDIRECT(K$5&"!$V$3:$AG$100"),12,0),0),"") | L38: =IFERROR(IF(VLOOKUP($C37,INDIRECT(L$5&"!$V$3:$AG$100"),12,0)>0,VLOOKUP($C37,INDIRECT(L$5&"!$V$3:$AG$100"),12,0),0),"") | M38: =IFERROR(IF(VLOOKUP($C37,INDIRECT(M$5&"!$V$3:$AG$100"),12,0)>0,VLOOKUP($C37,INDIRECT(M$5&"!$V$3:$AG$100"),12,0),0),"") | N38: =IFERROR(IF(VLOOKUP($C37,INDIRECT(N$5&"!$V$3:$AG$100"),12,0)>0,VLOOKUP($C37,INDIRECT(N$5&"!$V$3:$AG$100"),12,0),0),"") | O38: =IFERROR(IF(VLOOKUP($C37,INDIRECT(O$5&"!$V$3:$AG$100"),12,0)>0,VLOOKUP($C37,INDIRECT(O$5&"!$V$3:$AG$100"),12,0),0),"") | ... BG38: =IFERROR(IF(VLOOKUP($C37,INDIRECT(BG$5&"!$V$3:$AG$100"),12,0)>0,VLOOKUP($C37,INDIRECT(BG$5&"!$V$3:$AG$100"),12,0),0),"")
D39: =IF(C39="","",C39) | E39: =IF(B39="","",B39) | F39: P | G39: =SUM(H39:BG39) -> 0 | H39: =IFERROR(IF(VLOOKUP($C37,INDIRECT(H$5&"!$V$3:$AG$100"),11,0)>0,VLOOKUP($C37,INDIRECT(H$5&"!$V$3:$AG$100"),11,0),0),"") | I39: =IFERROR(IF(VLOOKUP($C37,INDIRECT(I$5&"!$V$3:$AG$100"),11,0)>0,VLOOKUP($C37,INDIRECT(I$5&"!$V$3:$AG$100"),11,0),0),"") | J39: =IFERROR(IF(VLOOKUP($C37,INDIRECT(J$5&"!$V$3:$AG$100"),11,0)>0,VLOOKUP($C37,INDIRECT(J$5&"!$V$3:$AG$100"),11,0),0),"") | K39: =IFERROR(IF(VLOOKUP($C37,INDIRECT(K$5&"!$V$3:$AG$100"),11,0)>0,VLOOKUP($C37,INDIRECT(K$5&"!$V$3:$AG$100"),11,0),0),"") | L39: =IFERROR(IF(VLOOKUP($C37,INDIRECT(L$5&"!$V$3:$AG$100"),11,0)>0,VLOOKUP($C37,INDIRECT(L$5&"!$V$3:$AG$100"),11,0),0),"") | M39: =IFERROR(IF(VLOOKUP($C37,INDIRECT(M$5&"!$V$3:$AG$100"),11,0)>0,VLOOKUP($C37,INDIRECT(M$5&"!$V$3:$AG$100"),11,0),0),"") | N39: =IFERROR(IF(VLOOKUP($C37,INDIRECT(N$5&"!$V$3:$AG$100"),11,0)>0,VLOOKUP($C37,INDIRECT(N$5&"!$V$3:$AG$100"),11,0),0),"") | O39: =IFERROR(IF(VLOOKUP($C37,INDIRECT(O$5&"!$V$3:$AG$100"),11,0)>0,VLOOKUP($C37,INDIRECT(O$5&"!$V$3:$AG$100"),11,0),0),"") | ... BG39: =IFERROR(IF(VLOOKUP($C37,INDIRECT(BG$5&"!$V$3:$AG$100"),11,0)>0,VLOOKUP($C37,INDIRECT(BG$5&"!$V$3:$AG$100"),11,0),0),"")
B40: L | C40: Heraldo Jr | D40: =IF(C40="","",C40) -> Heraldo Jr | E40: =IF(B40="","",B40) -> L | F40: A | G40: =SUM(H40:BG40) -> 23 | H40: =IFERROR(IF(VLOOKUP($C40,INDIRECT(H$5&"!$V$3:$AG$100"),2,0)>0,1,0),"") | I40: =IFERROR(IF(VLOOKUP($C40,INDIRECT(I$5&"!$V$3:$AG$100"),2,0)>0,1,0),"") -> 1 | J40: =IFERROR(IF(VLOOKUP($C40,INDIRECT(J$5&"!$V$3:$AG$100"),2,0)>0,1,0),"") -> 1 | K40: =IFERROR(IF(VLOOKUP($C40,INDIRECT(K$5&"!$V$3:$AG$100"),2,0)>0,1,0),"") | L40: =IFERROR(IF(VLOOKUP($C40,INDIRECT(L$5&"!$V$3:$AG$100"),2,0)>0,1,0),"") | M40: =IFERROR(IF(VLOOKUP($C40,INDIRECT(M$5&"!$V$3:$AG$100"),2,0)>0,1,0),"") | N40: =IFERROR(IF(VLOOKUP($C40,INDIRECT(N$5&"!$V$3:$AG$100"),2,0)>0,1,0),"") -> 1 | O40: =IFERROR(IF(VLOOKUP($C40,INDIRECT(O$5&"!$V$3:$AG$100"),2,0)>0,1,0),"") -> 1 | ... BG40: =IFERROR(IF(VLOOKUP($C40,INDIRECT(BG$5&"!$V$3:$AG$100"),2,0)>0,1,0),"")
D41: =IF(C41="","",C41) | E41: =IF(B41="","",B41) | F41: G | G41: =SUM(H41:BG41) -> 1 | H41: =IFERROR(IF(VLOOKUP($C40,INDIRECT(H$5&"!$V$3:$AG$100"),12,0)>0,VLOOKUP($C40,INDIRECT(H$5&"!$V$3:$AG$100"),12,0),0),"") | I41: =IFERROR(IF(VLOOKUP($C40,INDIRECT(I$5&"!$V$3:$AG$100"),12,0)>0,VLOOKUP($C40,INDIRECT(I$5&"!$V$3:$AG$100"),12,0),0),"") -> 0 | J41: =IFERROR(IF(VLOOKUP($C40,INDIRECT(J$5&"!$V$3:$AG$100"),12,0)>0,VLOOKUP($C40,INDIRECT(J$5&"!$V$3:$AG$100"),12,0),0),"") -> 0 | K41: =IFERROR(IF(VLOOKUP($C40,INDIRECT(K$5&"!$V$3:$AG$100"),12,0)>0,VLOOKUP($C40,INDIRECT(K$5&"!$V$3:$AG$100"),12,0),0),"") | L41: =IFERROR(IF(VLOOKUP($C40,INDIRECT(L$5&"!$V$3:$AG$100"),12,0)>0,VLOOKUP($C40,INDIRECT(L$5&"!$V$3:$AG$100"),12,0),0),"") | M41: =IFERROR(IF(VLOOKUP($C40,INDIRECT(M$5&"!$V$3:$AG$100"),12,0)>0,VLOOKUP($C40,INDIRECT(M$5&"!$V$3:$AG$100"),12,0),0),"") | N41: =IFERROR(IF(VLOOKUP($C40,INDIRECT(N$5&"!$V$3:$AG$100"),12,0)>0,VLOOKUP($C40,INDIRECT(N$5&"!$V$3:$AG$100"),12,0),0),"") -> 0 | O41: =IFERROR(IF(VLOOKUP($C40,INDIRECT(O$5&"!$V$3:$AG$100"),12,0)>0,VLOOKUP($C40,INDIRECT(O$5&"!$V$3:$AG$100"),12,0),0),"") -> 0 | ... BG41: =IFERROR(IF(VLOOKUP($C40,INDIRECT(BG$5&"!$V$3:$AG$100"),12,0)>0,VLOOKUP($C40,INDIRECT(BG$5&"!$V$3:$AG$100"),12,0),0),"")
...

Sheet Ranking
B2: Rank | C2: # | D2: Nome | E2: ="Assid. - "&TEXT(E41,"00") -> Assid. - 38 | F2: Nome | G2: Gols | H2: Nome | I2: Pontos | J2: Nome | K2: Gols/Jogo | L2: Nome | M2: Pontos/Jogo | O2: Mês | P2: Jogos | Q2: Média Presença
B3: 1 | C3: Z/V | D3: Andre | E3: =VLOOKUP($D3,Resumo!$C$7:$G$147,5,FALSE) -> 28 | F3: =D3 -> Andre | G3: {=INDEX(Resumo!$G:$G,MATCH(D3,Resumo!$C:$C,0)+1)} -> 2 | H3: =D3 -> Andre | I3: {=INDEX(Resumo!$G:$G,MATCH(D3,Resumo!$C:$C,0)+2)} -> 214 | J3: =F3 -> Andre | K3: =IF(E3<>0,G3/E3,0) -> 0.071428571 | L3: =H3 -> Andre | M3: =IF(E3<>0,I3/E3,0) -> 7.6428571 | O3: Janeiro | P3: =Resumo!H152 -> 3 | Q3: =Resumo!H163 -> 0.55882353
B4: =B3+1 -> 2 | C4: M/V | D4: Bigode | E4: =VLOOKUP($D4,Resumo!$C$7:$G$147,5,FALSE) -> 25 | F4: =D4 -> Bigode | G4: {=INDEX(Resumo!$G:$G,MATCH(D4,Resumo!$C:$C,0)+1)} -> 40 | H4: =D4 -> Bigode | I4: {=INDEX(Resumo!$G:$G,MATCH(D4,Resumo!$C:$C,0)+2)} -> 262 | J4: =F4 -> Bigode | K4: =IF(E4<>0,G4/E4,0) -> 1.6 | L4: =H4 -> Bigode | M4: =IF(E4<>0,I4/E4,0) -> 10.48 | O4: Fevereiro | P4: =Resumo!L152 -> 2 | Q4: =Resumo!L163 -> 0.66176471
B5: =B4+1 -> 3 | C5: A/M | D5: Comeli | E5: =VLOOKUP($D5,Resumo!$C$7:$G$147,5,FALSE) -> 32 | F5: =D5 -> Comeli | G5: {=INDEX(Resumo!$G:$G,MATCH(D5,Resumo!$C:$C,0)+1)} -> 60 | H5: =D5 -> Comeli | I5: {=INDEX(Resumo!$G:$G,MATCH(D5,Resumo!$C:$C,0)+2)} -> 264 | J5: =F5 -> Comeli | K5: =IF(E5<>0,G5/E5,0) -> 1.875 | L5: =H5 -> Comeli | M5: =IF(E5<>0,I5/E5,0) -> 8.25 | O5: Março | P5: =Resumo!P152 -> 5 | Q5: =Resumo!P163 -> 0.61176471
B6: =B5+1 -> 4 | C6: M/V | D6: Fabinho | E6: =VLOOKUP($D6,Resumo!$C$7:$G$147,5,FALSE) -> 29 | F6: =D6 -> Fabinho | G6: {=INDEX(Resumo!$G:$G,MATCH(D6,Resumo!$C:$C,0)+1)} -> 21 | H6: =D6 -> Fabinho | I6: {=INDEX(Resumo!$G:$G,MATCH(D6,Resumo!$C:$C,0)+2)} -> 220 | J6: =F6 -> Fabinho | K6: =IF(E6<>0,G6/E6,0) -> 0.72413793 | L6: =H6 -> Fabinho | M6: =IF(E6<>0,I6/E6,0) -> 7.5862069 | O6: Abril | P6: =Resumo!U152 -> 3 | Q6: =Resumo!U163 -> 0.6372549
B7: =B6+1 -> 5 | C7: G | D7: Fabio | E7: =VLOOKUP($D7,Resumo!$C$7:$G$147,5,FALSE) -> 25 | F7: =D7 -> Fabio | G7: {=INDEX(Resumo!$G:$G,MATCH(D7,Resumo!$C:$C,0)+1)} -> 0 | H7: =D7 -> Fabio | I7: {=INDEX(Resumo!$G:$G,MATCH(D7,Resumo!$C:$C,0)+2)} -> 233 | J7: =F7 -> Fabio | K7: =IF(E7<>0,G7/E7,0) -> 0 | L7: =H7 -> Fabio | M7: =IF(E7<>0,I7/E7,0) -> 9.32 | O7: Maio | P7: =Resumo!Y152 -> 4 | Q7: =Resumo!Y163 -> 0.52941176
B8: =B7+1 -> 6 | C8: M/LE | D8: Felipo | E8: =VLOOKUP($D8,Resumo!$C$7:$G$147,5,FALSE) -> 13 | F8: =D8 -> Felipo | G8: {=INDEX(Resumo!$G:$G,MATCH(D8,Resumo!$C:$C,0)+1)} -> 2 | H8: =D8 -> Felipo | I8: {=INDEX(Resumo!$G:$G,MATCH(D8,Resumo!$C:$C,0)+2)} -> 91 | J8: =F8 -> Felipo | K8: =IF(E8<>0,G8/E8,0) -> 0.15384615 | L8: =H8 -> Felipo | M8: =IF(E8<>0,I8/E8,0) -> 7 | O8: Junho | P8: =Resumo!AC152 -> 2 | Q8: =Resumo!AC163 -> 0.61764706
B9: =B8+1 -> 7 | C9: Z/LE | D9: Fernando | E9: =VLOOKUP($D9,Resumo!$C$7:$G$147,5,FALSE) -> 23 | F9: =D9 -> Fernando | G9: {=INDEX(Resumo!$G:$G,MATCH(D9,Resumo!$C:$C,0)+1)} -> 13 | H9: =D9 -> Fernando | I9: {=INDEX(Resumo!$G:$G,MATCH(D9,Resumo!$C:$C,0)+2)} -> 161 | J9: =F9 -> Fernando | K9: =IF(E9<>0,G9/E9,0) -> 0.56521739 | L9: =H9 -> Fernando | M9: =IF(E9<>0,I9/E9,0) -> 7 | O9: Julho | P9: =Resumo!AH152 -> 4 | Q9: =Resumo!AH163 -> 0.5
B10: =B9+1 -> 8 | C10: V/M | D10: Fumagalli | E10: =VLOOKUP($D10,Resumo!$C$7:$G$147,5,FALSE) -> 18 | F10: =D10 -> Fumagalli | G10: {=INDEX(Resumo!$G:$G,MATCH(D10,Resumo!$C:$C,0)+1)} -> 8 | H10: =D10 -> Fumagalli | I10: {=INDEX(Resumo!$G:$G,MATCH(D10,Resumo!$C:$C,0)+2)} -> 139 | J10: =F10 -> Fumagalli | K10: =IF(E10<>0,G10/E10,0) -> 0.44444444 | L10: =H10 -> Fumagalli | M10: =IF(E10<>0,I10/E10,0) -> 7.7222222 | O10: Agosto | P10: =Resumo!AL152 -> 4 | Q10: =Resumo!AL163 -> 0.43382353
B11: =B10+1 -> 9 | C11: M/A | D11: Gabriel | E11: =VLOOKUP($D11,Resumo!$C$7:$G$147,5,FALSE) -> 19 | F11: =D11 -> Gabriel | G11: {=INDEX(Resumo!$G:$G,MATCH(D11,Resumo!$C:$C,0)+1)} -> 27 | H11: =D11 -> Gabriel | I11: {=INDEX(Resumo!$G:$G,MATCH(D11,Resumo!$C:$C,0)+2)} -> 115 | J11: =F11 -> Gabriel | K11: =IF(E11<>0,G11/E11,0) -> 1.4210526 | L11: =H11 -> Gabriel | M11: =IF(E11<>0,I11/E11,0) -> 6.0526316 | O11: Setembro | P11: =Resumo!AQ152 -> 4 | Q11: =Resumo!AQ163 -> 0.41911765
B12: =B11+1 -> 10 | C12: M/A | D12: Guilherme | E12: =VLOOKUP($D12,Resumo!$C$7:$G$147,5,FALSE) -> 33 | F12: =D12 -> Guilherme | G12: {=INDEX(Resumo!$G:$G,MATCH(D12,Resumo!$C:$C,0)+1)} -> 68 | H12: =D12 -> Guilherme | I12: {=INDEX(Resumo!$G:$G,MATCH(D12,Resumo!$C:$C,0)+2)} -> 258 | J12: =F12 -> Guilherme | K12: =IF(E12<>0,G12/E12,0) -> 2.0606061 | L12: =H12 -> Guilherme | M12: =IF(E12<>0,I12/E12,0) -> 7.8181818 | O12: Outubro | P12: =Resumo!AU152 -> 3 | Q12: =Resumo!AU163 -> 0.5
B13: =B12+1 -> 11 | C13: A/M | D13: Heraldo | E13: =VLOOKUP($D13,Resumo!$C$7:$G$147,5,FALSE) -> 20 | F13: =D13 -> Heraldo | G13: {=INDEX(Resumo!$G:$G,MATCH(D13,Resumo!$C:$C,0)+1)} -> 17 | H13: =D13 -> Heraldo | I13: {=INDEX(Resumo!$G:$G,MATCH(D13,Resumo!$C:$C,0)+2)} -> 137 | J13: =F13 -> Heraldo | K13: =IF(E13<>0,G13/E13,0) -> 0.85 | L13: =H13 -> Heraldo | M13: =IF(E13<>0,I13/E13,0) -> 6.85 | O13: Novembro | P13: =Resumo!AY152 -> 4 | Q13: =Resumo!AY163 -> 0.50735294
B14: =B13+1 -> 12 | C14: LD/LE | D14: Heraldo Jr | E14: =VLOOKUP($D14,Resumo!$C$7:$G$147,5,FALSE) -> 23 | F14: =D14 -> Heraldo Jr | G14: {=INDEX(Resumo!$G:$G,MATCH(D14,Resumo!$C:$C,0)+1)} -> 1 | H14: =D14 -> Heraldo Jr | I14: {=INDEX(Resumo!$G:$G,MATCH(D14,Resumo!$C:$C,0)+2)} -> 199 | J14: =F14 -> Heraldo Jr | K14: =IF(E14<>0,G14/E14,0) -> 0.043478261 | L14: =H14 -> Heraldo Jr | M14: =IF(E14<>0,I14/E14,0) -> 8.6521739 | O14: Dezembro | P14: =Resumo!BD152 -> 0 | Q14: =Resumo!BD163 -> 0
B15: =B14+1 -> 13 | C15: V/Z | D15: Hugo | E15: =VLOOKUP($D15,Resumo!$C$7:$G$147,5,FALSE) -> 37 | F15: =D15 -> Hugo | G15: {=INDEX(Resumo!$G:$G,MATCH(D15,Resumo!$C:$C,0)+1)} -> 20 | H15: =D15 -> Hugo | I15: {=INDEX(Resumo!$G:$G,MATCH(D15,Resumo!$C:$C,0)+2)} -> 302 | J15: =F15 -> Hugo | K15: =IF(E15<>0,G15/E15,0) -> 0.54054054 | L15: =H15 -> Hugo | M15: =IF(E15<>0,I15/E15,0) -> 8.1621622 | O15: Total | P15: =SUM(P3:P14) -> 38 | Q15: =Resumo!BI160 -> 0.53328173
B16: =B15+1 -> 14 | C16: LE/Z | D16: Joao | E16: =VLOOKUP($D16,Resumo!$C$7:$G$147,5,FALSE) -> 13 | F16: =D16 -> Joao | G16: {=INDEX(Resumo!$G:$G,MATCH(D16,Resumo!$C:$C,0)+1)} -> 3 | H16: =D16 -> Joao | I16: {=INDEX(Resumo!$G:$G,MATCH(D16,Resumo!$C:$C,0)+2)} -> 78 | J16: =F16 -> Joao | K16: =IF(E16<>0,G16/E16,0) -> 0.23076923 | L16: =H16 -> Joao | M16: =IF(E16<>0,I16/E16,0) -> 6
B17: =B16+1 -> 15 | C17: M/LD | D17: John | E17: =VLOOKUP($D17,Resumo!$C$7:$G$147,5,FALSE) -> 9 | F17: =D17 -> John | G17: {=INDEX(Resumo!$G:$G,MATCH(D17,Resumo!$C:$C,0)+1)} -> 3 | H17: =D17 -> John | I17: {=INDEX(Resumo!$G:$G,MATCH(D17,Resumo!$C:$C,0)+2)} -> 61 | J17: =F17 -> John | K17: =IF(E17<>0,G17/E17,0) -> 0.33333333 | L17: =H17 -> John | M17: =IF(E17<>0,I17/E17,0) -> 6.7777778
B18: =B17+1 -> 16 | C18: V/LD | D18: Juba | E18: =VLOOKUP($D18,Resumo!$C$7:$G$147,5,FALSE) -> 22 | F18: =D18 -> Juba | G18: {=INDEX(Resumo!$G:$G,MATCH(D18,Resumo!$C:$C,0)+1)} -> 10 | H18: =D18 -> Juba | I18: {=INDEX(Resumo!$G:$G,MATCH(D18,Resumo!$C:$C,0)+2)} -> 158 | J18: =F18 -> Juba | K18: =IF(E18<>0,G18/E18,0) -> 0.45454545 | L18: =H18 -> Juba | M18: =IF(E18<>0,I18/E18,0) -> 7.1818182
B19: =B18+1 -> 17 | C19: A/M | D19: Junior | E19: =VLOOKUP($D19,Resumo!$C$7:$G$147,5,FALSE) -> 4 | F19: =D19 -> Junior | G19: {=INDEX(Resumo!$G:$G,MATCH(D19,Resumo!$C:$C,0)+1)} -> 2 | H19: =D19 -> Junior | I19: {=INDEX(Resumo!$G:$G,MATCH(D19,Resumo!$C:$C,0)+2)} -> 17 | J19: =F19 -> Junior | K19: =IF(E19<>0,G19/E19,0) -> 0.5 | L19: =H19 -> Junior | M19: =IF(E19<>0,I19/E19,0) -> 4.25
B20: =B19+1 -> 18 | C20: M/A | D20: Kandido | E20: =VLOOKUP($D20,Resumo!$C$7:$G$147,5,FALSE) -> 15 | F20: =D20 -> Kandido | G20: {=INDEX(Resumo!$G:$G,MATCH(D20,Resumo!$C:$C,0)+1)} -> 23 | H20: =D20 -> Kandido | I20: {=INDEX(Resumo!$G:$G,MATCH(D20,Resumo!$C:$C,0)+2)} -> 114 | J20: =F20 -> Kandido | K20: =IF(E20<>0,G20/E20,0) -> 1.5333333 | L20: =H20 -> Kandido | M20: =IF(E20<>0,I20/E20,0) -> 7.6
B21: =B20+1 -> 19 | C21: Z/LD | D21: Kike | E21: =VLOOKUP($D21,Resumo!$C$7:$G$147,5,FALSE) -> 15 | F21: =D21 -> Kike | G21: {=INDEX(Resumo!$G:$G,MATCH(D21,Resumo!$C:$C,0)+1)} -> 1 | H21: =D21 -> Kike | I21: {=INDEX(Resumo!$G:$G,MATCH(D21,Resumo!$C:$C,0)+2)} -> 80 | J21: =F21 -> Kike | K21: =IF(E21<>0,G21/E21,0) -> 0.066666667 | L21: =H21 -> Kike | M21: =IF(E21<>0,I21/E21,0) -> 5.3333333
B22: =B21+1 -> 20 | C22: M/V | D22: Lazzari | E22: =VLOOKUP($D22,Resumo!$C$7:$G$147,5,FALSE) -> 27 | F22: =D22 -> Lazzari | G22: {=INDEX(Resumo!$G:$G,MATCH(D22,Resumo!$C:$C,0)+1)} -> 22 | H22: =D22 -> Lazzari | I22: {=INDEX(Resumo!$G:$G,MATCH(D22,Resumo!$C:$C,0)+2)} -> 216 | J22: =F22 -> Lazzari | K22: =IF(E22<>0,G22/E22,0) -> 0.81481481 | L22: =H22 -> Lazzari | M22: =IF(E22<>0,I22/E22,0) -> 8
B23: =B22+1 -> 21 | C23: LD/Z | D23: Leandro | E23: =VLOOKUP($D23,Resumo!$C$7:$G$147,5,FALSE) -> 18 | F23: =D23 -> Leandro | G23: {=INDEX(Resumo!$G:$G,MATCH(D23,Resumo!$C:$C,0)+1)} -> 2 | H23: =D23 -> Leandro | I23: {=INDEX(Resumo!$G:$G,MATCH(D23,Resumo!$C:$C,0)+2)} -> 110 | J23: =F23 -> Leandro | K23: =IF(E23<>0,G23/E23,0) -> 0.11111111 | L23: =H23 -> Leandro | M23: =IF(E23<>0,I23/E23,0) -> 6.1111111
B24: =B23+1 -> 22 | C24: LE/G | D24: Leo | E24: =VLOOKUP($D24,Resumo!$C$7:$G$147,5,FALSE) -> 20 | F24: =D24 -> Leo | G24: {=INDEX(Resumo!$G:$G,MATCH(D24,Resumo!$C:$C,0)+1)} -> 7 | H24: =D24 -> Leo | I24: {=INDEX(Resumo!$G:$G,MATCH(D24,Resumo!$C:$C,0)+2)} -> 156 | J24: =F24 -> Leo | K24: =IF(E24<>0,G24/E24,0) -> 0.35 | L24: =H24 -> Leo | M24: =IF(E24<>0,I24/E24,0) -> 7.8
B25: =B24+1 -> 23 | C25: LD/M | D25: Luiz | E25: =VLOOKUP($D25,Resumo!$C$7:$G$147,5,FALSE) -> 29 | F25: =D25 -> Luiz | G25: {=INDEX(Resumo!$G:$G,MATCH(D25,Resumo!$C:$C,0)+1)} -> 16 | H25: =D25 -> Luiz | I25: {=INDEX(Resumo!$G:$G,MATCH(D25,Resumo!$C:$C,0)+2)} -> 189 | J25: =F25 -> Luiz | K25: =IF(E25<>0,G25/E25,0) -> 0.55172414 | L25: =H25 -> Luiz | M25: =IF(E25<>0,I25/E25,0) -> 6.5172414
B26: =B25+1 -> 24 | C26: LE/V | D26: Luiz Fernando | E26: =VLOOKUP($D26,Resumo!$C$7:$G$147,5,FALSE) -> 29 | F26: =D26 -> Luiz Fernando | G26: {=INDEX(Resumo!$G:$G,MATCH(D26,Resumo!$C:$C,0)+1)} -> 3 | H26: =D26 -> Luiz Fernando | I26: {=INDEX(Resumo!$G:$G,MATCH(D26,Resumo!$C:$C,0)+2)} -> 200 | J26: =F26 -> Luiz Fernando | K26: =IF(E26<>0,G26/E26,0) -> 0.10344828 | L26: =H26 -> Luiz Fernando | M26: =IF(E26<>0,I26/E26,0) -> 6.8965517
B27: =B26+1 -> 25 | C27: M/V | D27: Marcelo | E27: =VLOOKUP($D27,Resumo!$C$7:$G$147,5,FALSE) -> 34 | F27: =D27 -> Marcelo | G27: {=INDEX(Resumo!$G:$G,MATCH(D27,Resumo!$C:$C,0)+1)} -> 20 | H27: =D27 -> Marcelo | I27: {=INDEX(Resumo!$G:$G,MATCH(D27,Resumo!$C:$C,0)+2)} -> 198 | J27: =F27 -> Marcelo | K27: =IF(E27<>0,G27/E27,0) -> 0.58823529 | L27: =H27 -> Marcelo | M27: =IF(E27<>0,I27/E27,0) -> 5.8235294
... B36: =B35+1 -> 34 | C36: V/Z | D36: Xinho | E36: =VLOOKUP($D36,Resumo!$C$7:$G$147,5,FALSE) -> 15 | F36: =D36 -> Xinho | G36: {=INDEX(Resumo!$G:$G,MATCH(D36,Resumo!$C:$C,0)+1)} -> 7 | H36: =D36 -> Xinho | I36: {=INDEX(Resumo!$G:$G,MATCH(D36,Resumo!$C:$C,0)+2)} -> 111 | J36: =F36 -> Xinho | K36: =IF(E36<>0,G36/E36,0) -> 0.46666667 | L36: =H36 -> Xinho | M36: =IF(E36<>0,I36/E36,0) -> 7.4
E41: =Resumo!C150 -> 38

Sheet Estat. Seleção
B1: Total de Jogos | D1: =Resumo!C150 -> 38
B2: Rank | C2: # | D2: Nome | E2: Seleção | F2: Nome | G2: Seleção/Domingo | H2: Nome | I2: Seleção/Total | J2: Nome | K2: % Presença | L2: Nome
B3: 1 | C3: V/Z | D3: Hugo | E3: 21 | F3: =D3 -> Hugo | G3: =E3/VLOOKUP($D3,Resumo!$C$7:$G$147,5,FALSE) -> 0.56756757 | H3: =D3 -> Hugo | I3: =E3/Resumo!$C$150 -> 0.55263158 | J3: =F3 -> Hugo | K3: =VLOOKUP($D3,Resumo!$C$7:$G$147,5,FALSE)/Resumo!$C$150 -> 0.97368421 | L3: =H3 -> Hugo
B4: =B3+1 -> 2 | C4: M/V | D4: Marcelo | E4: 13 | F4: =D4 -> Marcelo | G4: =E4/VLOOKUP($D4,Resumo!$C$7:$G$147,5,FALSE) -> 0.38235294 | H4: =D4 -> Marcelo | I4: =E4/Resumo!$C$150 -> 0.34210526 | J4: =F4 -> Marcelo | K4: =VLOOKUP($D4,Resumo!$C$7:$G$147,5,FALSE)/Resumo!$C$150 -> 0.89473684 | L4: =H4 -> Marcelo
B5: =B4+1 -> 3 | C5: M/A | D5: Guilherme | E5: 14 | F5: =D5 -> Guilherme | G5: =E5/VLOOKUP($D5,Resumo!$C$7:$G$147,5,FALSE) -> 0.42424242 | H5: =D5 -> Guilherme | I5: =E5/Resumo!$C$150 -> 0.36842105 | J5: =F5 -> Guilherme | K5: =VLOOKUP($D5,Resumo!$C$7:$G$147,5,FALSE)/Resumo!$C$150 -> 0.86842105 | L5: =H5 -> Guilherme
B6: =B5+1 -> 4 | C6: A/M | D6: Comeli | E6: 15 | F6: =D6 -> Comeli | G6: =E6/VLOOKUP($D6,Resumo!$C$7:$G$147,5,FALSE) -> 0.46875 | H6: =D6 -> Comeli | I6: =E6/Resumo!$C$150 -> 0.39473684 | J6: =F6 -> Comeli | K6: =VLOOKUP($D6,Resumo!$C$7:$G$147,5,FALSE)/Resumo!$C$150 -> 0.84210526 | L6: =H6 -> Comeli
B7: =B6+1 -> 5 | C7: M/V | D7: Fabinho | E7: 13 | F7: =D7 -> Fabinho | G7: =E7/VLOOKUP($D7,Resumo!$C$7:$G$147,5,FALSE) -> 0.44827586 | H7: =D7 -> Fabinho | I7: =E7/Resumo!$C$150 -> 0.34210526 | J7: =F7 -> Fabinho | K7: =VLOOKUP($D7,Resumo!$C$7:$G$147,5,FALSE)/Resumo!$C$150 -> 0.76315789 | L7: =H7 -> Fabinho
B8: =B7+1 -> 6 | C8: LD/M | D8: Luiz | E8: 13 | F8: =D8 -> Luiz | G8: =E8/VLOOKUP($D8,Resumo!$C$7:$G$147,5,FALSE) -> 0.44827586 | H8: =D8 -> Luiz | I8: =E8/Resumo!$C$150 -> 0.34210526 | J8: =F8 -> Luiz | K8: =VLOOKUP($D8,Resumo!$C$7:$G$147,5,FALSE)/Resumo!$C$150 -> 0.76315789 | L8: =H8 -> Luiz
B9: =B8+1 -> 7 | C9: LE/V | D9: Luiz Fernando | E9: 14 | F9: =D9 -> Luiz Fernando | G9: =E9/VLOOKUP($D9,Resumo!$C$7:$G$147,5,FALSE) -> 0.48275862 | H9: =D9 -> Luiz Fernando | I9: =E9/Resumo!$C$150 -> 0.36842105 | J9: =F9 -> Luiz Fernando | K9: =VLOOKUP($D9,Resumo!$C$7:$G$147,5,FALSE)/Resumo!$C$150 -> 0.76315789 | L9: =H9 -> Luiz Fernando
B10: =B9+1 -> 8 | C10: Z/V | D10: Andre | E10: 14 | F10: =D10 -> Andre | G10: =E10/VLOOKUP($D10,Resumo!$C$7:$G$147,5,FALSE) -> 0.5 | H10: =D10 -> Andre | I10: =E10/Resumo!$C$150 -> 0.36842105 | J10: =F10 -> Andre | K10: =VLOOKUP($D10,Resumo!$C$7:$G$147,5,FALSE)/Resumo!$C$150 -> 0.73684211 | L10: =H10 -> Andre
B11: =B10+1 -> 9 | C11: M/V | D11: Lazzari | E11: 14 | F11: =D11 -> Lazzari | G11: =E11/VLOOKUP($D11,Resumo!$C$7:$G$147,5,FALSE) -> 0.51851852 | H11: =D11 -> Lazzari | I11: =E11/Resumo!$C$150 -> 0.36842105 | J11: =F11 -> Lazzari | K11: =VLOOKUP($D11,Resumo!$C$7:$G$147,5,FALSE)/Resumo!$C$150 -> 0.71052632 | L11: =H11 -> Lazzari
B12: =B11+1 -> 10 | C12: M/V | D12: Bigode | E12: 19 | F12: =D12 -> Bigode | G12: =E12/VLOOKUP($D12,Resumo!$C$7:$G$147,5,FALSE) -> 0.76 | H12: =D12 -> Bigode | I12: =E12/Resumo!$C$150 -> 0.5 | J12: =F12 -> Bigode | K12: =VLOOKUP($D12,Resumo!$C$7:$G$147,5,FALSE)/Resumo!$C$150 -> 0.65789474 | L12: =H12 -> Bigode
B13: =B12+1 -> 11 | C13: Z/LE | D13: Fernando | E13: 9 | F13: =D13 -> Fernando | G13: =E13/VLOOKUP($D13,Resumo!$C$7:$G$147,5,FALSE) -> 0.39130435 | H13: =D13 -> Fernando | I13: =E13/Resumo!$C$150 -> 0.23684211 | J13: =F13 -> Fernando | K13: =VLOOKUP($D13,Resumo!$C$7:$G$147,5,FALSE)/Resumo!$C$150 -> 0.60526316 | L13: =H13 -> Fernando
B14: =B13+1 -> 12 | C14: LD/LE | D14: Heraldo Jr | E14: 13 | F14: =D14 -> Heraldo Jr | G14: =E14/VLOOKUP($D14,Resumo!$C$7:$G$147,5,FALSE) -> 0.56521739 | H14: =D14 -> Heraldo Jr | I14: =E14/Resumo!$C$150 -> 0.34210526 | J14: =F14 -> Heraldo Jr | K14: =VLOOKUP($D14,Resumo!$C$7:$G$147,5,FALSE)/Resumo!$C$150 -> 0.60526316 | L14: =H14 -> Heraldo Jr
B15: =B14+1 -> 13 | C15: LD/M | D15: Rafa Silva | E15: 10 | F15: =D15 -> Rafa Silva | G15: =E15/VLOOKUP($D15,Resumo!$C$7:$G$147,5,FALSE) -> 0.43478261 | H15: =D15 -> Rafa Silva | I15: =E15/Resumo!$C$150 -> 0.26315789 | J15: =F15 -> Rafa Silva | K15: =VLOOKUP($D15,Resumo!$C$7:$G$147,5,FALSE)/Resumo!$C$150 -> 0.60526316 | L15: =H15 -> Rafa Silva
... B36: =B35+1 -> 34 | C36: G | D36: Ralph | E36: 9 | F36: =D36 -> Ralph | G36: =E36/VLOOKUP($D36,Resumo!$C$7:$G$147,5,FALSE) -> 0.33333333 | H36: =D36 -> Ralph | I36: =E36/Resumo!$C$150 -> 0.23684211 | J36: =F36 -> Ralph | K36: =VLOOKUP($D36,Resumo!$C$7:$G$147,5,FALSE)/Resumo!$C$150 -> 0.71052632 | L36: =H36 -> Ralph

Sheet T
K2: =MID(CELL("filename",A1),FIND("]",CELL("filename",A1))+1,255) -> T | U2: # | V2: Nome | W2: J | X2: GF | Y2: GS | Z2: V | AA2: E | AB2: D | AC2: P | AD2: % | AE2: Extra | AF2: PT | AG2: Gols | AH2: GS/J | AI2: GF/J
K3: Jogo1 | U3: G | W3: =COUNTIF($C$2:$C$123,V3)+COUNTIF($S$2:$S$123,V3) -> 16 | X3: =SUMIF($C$2:$C$123,V3,$F$2:$F$123)+SUMIF($S$2:$S$123,V3,$M$2:$M$123) -> 0 | Y3: =SUMIF($C$2:$C$123,V3,$G$2:$G$123)+SUMIF($S$2:$S$123,V3,$N$2:$N$123) -> 0 | Z3: =SUMIF($C$2:$C$123,V3,$H$2:$H$123)+SUMIF($S$2:$S$123,V3,$O$2:$O$123) -> 0 | AA3: =SUMIF($C$2:$C$123,V3,$I$2:$I$123)+SUMIF($S$2:$S$123,V3,$P$2:P$123) -> 8 | AB3: =SUMIF($C$2:$C$123,V3,$J$2:$J$123)+SUMIF($S$2:$S$123,V3,$Q$2:$Q$123) -> 0 | AC3: =SUMIF($C$2:$C$123,V3,$E$2:$E$123)+SUMIF($S$2:$S$123,V3,$L$2:$L$123) -> 8 | AD3: =IFERROR(IF(W3>=($AI$42*$AI$43),(AC3)/(W3*3),"-"),"-") -> 0.16666667 | AE3: =IF(W3>0,IF(AH3=MIN($AH$3:$AH$5),2,0),) -> 2 | AF3: =IF(W3>0,IF(AD3=MAX($AD$3:$AD$5),AC3+AE3+2,AC3+AE3),) -> 12 | AG3: =SUMIF($C$2:$C$123,V3,$D$2:$D$123)+SUMIF($S$2:$S$123,V3,$R$2:$R$123) -> 0 | AH3: =IFERROR(IF(W3>=($AI$42*$AI$43),Y3/W3,"-"),"-") -> 0 | AI3: =IFERROR(IF(W3>=($AI$42*$AI$43),X3/W3,"-"),"-") -> 0
D4: =SUM(D5:D14) -> 0 | E4: P | F4: GA | G4: GC | H4: V | I4: E | J4: D | K4: x | L4: P | M4: GA | N4: GC | O4: V | P4: E | Q4: D | R4: =SUM(R5:R14) -> 0 | U4: G | W4: =COUNTIF($C$2:$C$123,V4)+COUNTIF($S$2:$S$123,V4) -> 16 | X4: =SUMIF($C$2:$C$123,V4,$F$2:$F$123)+SUMIF($S$2:$S$123,V4,$M$2:$M$123) -> 0 | Y4: =SUMIF($C$2:$C$123,V4,$G$2:$G$123)+SUMIF($S$2:$S$123,V4,$N$2:$N$123) -> 0 | Z4: =SUMIF($C$2:$C$123,V4,$H$2:$H$123)+SUMIF($S$2:$S$123,V4,$O$2:$O$123) -> 0 | AA4: =SUMIF($C$2:$C$123,V4,$I$2:$I$123)+SUMIF($S$2:$S$123,V4,$P$2:P$123) -> 8 | AB4: =SUMIF($C$2:$C$123,V4,$J$2:$J$123)+SUMIF($S$2:$S$123,V4,$Q$2:$Q$123) -> 0 | AC4: =SUMIF($C$2:$C$123,V4,$E$2:$E$123)+SUMIF($S$2:$S$123,V4,$L$2:$L$123) -> 8 | AD4: =IFERROR(IF(W4>=($AI$42*$AI$43),(AC4)/(W4*3),"-"),"-") -> 0.16666667 | AE4: =IF(W4>0,IF(AH4=MIN($AH$3:$AH$5),2,0),) -> 2 | AF4: =IF(W4>0,IF(AD4=MAX($AD$3:$AD$5),AC4+AE4+2,AC4+AE4),) -> 12 | AG4: =SUMIF($C$2:$C$123,V4,$D$2:$D$123)+SUMIF($S$2:$S$123,V4,$R$2:$R$123) -> 0 | AH4: =IFERROR(IF(W4>=($AI$42*$AI$43),Y4/W4,"-"),"-") -> 0 | AI4: =IFERROR(IF(W4>=($AI$42*$AI$43),X4/W4,"-"),"-") -> 0
B5: G | E5: =IF((C5=""),0,IF($D$4=$R$4,1,IF($D$4>$R$4,3,IF($D$4<$R$4,0)))) -> 0 | F5: =$D$4 -> 0 | G5: =$R$4 -> 0 | H5: =IF((C5=""),0,IF($D$4>$R$4,1,0)) -> 0 | I5: =IF((C5=""),0,IF($D$4=$R$4,1,0)) -> 0 | J5: =IF((C5=""),0,IF($D$4<$R$4,1,0)) -> 0 | L5: =IF((S5=""),0,IF($D$4=$R$4,1,IF($D$4<$R$4,3,IF($D$4>$R$4,0)))) -> 0 | M5: =$R$4 -> 0 | N5: =$D$4 -> 0 | O5: =IF((S5=""),0,IF($D$4<$R$4,1,0)) -> 0 | P5: =IF((S5=""),0,IF($D$4=$R$4,1,0)) -> 0 | Q5: =IF((S5=""),0,IF($D$4>$R$4,1,0)) -> 0 | U5: G | W5: =COUNTIF($C$2:$C$123,V5)+COUNTIF($S$2:$S$123,V5) -> 16 | X5: =SUMIF($C$2:$C$123,V5,$F$2:$F$123)+SUMIF($S$2:$S$123,V5,$M$2:$M$123) -> 0 | Y5: =SUMIF($C$2:$C$123,V5,$G$2:$G$123)+SUMIF($S$2:$S$123,V5,$N$2:$N$123) -> 0 | Z5: =SUMIF($C$2:$C$123,V5,$H$2:$H$123)+SUMIF($S$2:$S$123,V5,$O$2:$O$123) -> 0 | AA5: =SUMIF($C$2:$C$123,V5,$I$2:$I$123)+SUMIF($S$2:$S$123,V5,$P$2:P$123) -> 8 | AB5: =SUMIF($C$2:$C$123,V5,$J$2:$J$123)+SUMIF($S$2:$S$123,V5,$Q$2:$Q$123) -> 0 | AC5: =SUMIF($C$2:$C$123,V5,$E$2:$E$123)+SUMIF($S$2:$S$123,V5,$L$2:$L$123) -> 8 | AD5: =IFERROR(IF(W5>=($AI$42*$AI$43),(AC5)/(W5*3),"-"),"-") -> 0.16666667 | AE5: =IF(W5>0,IF(AH5=MIN($AH$3:$AH$5),2,0),) -> 2 | AF5: =IF(W5>0,IF(AD5=MAX($AD$3:$AD$5),AC5+AE5+2,AC5+AE5),) -> 12 | AG5: =SUMIF($C$2:$C$123,V5,$D$2:$D$123)+SUMIF($S$2:$S$123,V5,$R$2:$R$123) -> 0 | AH5: =IFERROR(IF(W5>=($AI$42*$AI$43),Y5/W5,"-"),"-") -> 0 | AI5: =IFERROR(IF(W5>=($AI$42*$AI$43),X5/W5,"-"),"-") -> 0
